Workbook

Sheet Cover
B7: Financial Modeling - Practice
B11: Adani Power
B12: Sep 25, 2026
B16: Disclaimer: This analysis is not a solicitation, offer, or recommendation to buy, hold, or sell any security, commodity, or financial instrument. This financial model and the accompanying analysis are for educational, practice, and informational purposes only. Nothing contained in this post or model constitutes financial, investment, legal, or tax advice. Harsh Aryan 2026 © — shared for educational purposes; please credit if referenced

Sheet Data & Assumption >>

Sheet Historical Data
B1: =Cover!B11 -> Adani Power
A2: # | B2: Income Statement
B3: (₹ Crore)
H5: 2017 | I5: =H5+1 -> 2018 | J5: =I5+1 -> 2019 | K5: =J5+1 -> 2020 | L5: =K5+1 -> 2021 | M5: =L5+1 -> 2022 | N5: =M5+1 -> 2023 | O5: =N5+1 -> 2024 | P5: =O5+1 -> 2025 | Q5: =P5+1 -> 2026
B7: Revenue
C8: Sales | H8: 22615.51 | I8: 20304.28 | J8: 23884.18 | K8: 26467.72 | L8: 26221.48 | M8: 27711.18 | N8: 38773.3 | O8: 50351.25 | P8: 56203.09 | Q8: 54240.52
B10: COGS
C11: Power and Fuel | H11: 14630.49 | I11: 12535.25 | J11: 15952.45 | K11: 17580.39 | L11: 14781.15 | M11: 14762.21 | N11: 25480.85 | O11: 28452.64 | P11: 30273.25 | Q11: 29168.02
C12: Other Mfr. Exp | H12: 1260.02 | I12: 1551.86 | J12: 1680.59 | K12: 1864.95 | L12: 1838.18 | M12: 2066.68 | N12: 1718.27 | O12: 1856.84 | P12: 2231.05 | Q12: 2565.39
C13: Gross Profit | H13: =H8-SUM(H11:H12) -> 6725 | I13: =I8-SUM(I11:I12) -> 6217.17 | J13: =J8-SUM(J11:J12) -> 6251.14 | K13: =K8-SUM(K11:K12) -> 7022.38 | L13: =L8-SUM(L11:L12) -> 9602.15 | M13: =M8-SUM(M11:M12) -> 10882.29 | N13: =N8-SUM(N11:N12) -> 11574.18 | O13: =O8-SUM(O11:O12) -> 20041.77 | ... Q13: =Q8-SUM(Q11:Q12) -> 22507.11
B15: SG&A
C16: Employee Cost | H16: 361.01 | I16: 353.9 | J16: 363.47 | K16: 427.04 | L16: 431.89 | M16: 470.72 | N16: 570.46 | O16: 644.17 | P16: 786.63 | Q16: 857.81
C17: Selling and admin | H17: 307.25 | I17: 225.3 | J17: 222.73 | K17: 454.63 | L17: 281.14 | M17: 233.67 | N17: 443.65 | O17: 454.82 | P17: 543.57 | Q17: 581.01
C18: Other Expenses | H18: 76.7 | I18: 202.04 | J18: 681.53 | K18: 407.07 | L18: 200.96 | M18: 296.49 | N18: 463.73 | O18: 715.16 | P18: 950.26 | Q18: 1262.18
C19: Other Income | H19: -3666.12 | I19: 754.1 | J19: 2447.87 | K19: 322.76 | L19: 1908.56 | M19: 3908.04 | N19: 4215.54 | O19: 9883.31 | P19: 2589.85 | Q19: 3624.76
C20: EBITDA | H20: =H13-SUM(H16:H18)+H19 -> 2313.92 | I20: =I13-SUM(I16:I18)+I19 -> 6190.03 | J20: =J13-SUM(J16:J18)+J19 -> 7431.28 | K20: =K13-SUM(K16:K18)+K19 -> 6056.4 | L20: =L13-SUM(L16:L18)+L19 -> 10596.72 | M20: =M13-SUM(M16:M18)+M19 -> 13789.45 | N20: =N13-SUM(N16:N18)+N19 -> 14311.88 | O20: =O13-SUM(O16:O18)+O19 -> 28110.93 | ... Q20: =Q13-SUM(Q16:Q18)+Q19 -> 23430.87
C22: Depreciation | H22: 2672.36 | I22: 2698.72 | J22: 2750.62 | K22: 3006.5 | L22: 3201.65 | M22: 3117.54 | N22: 3303.68 | O22: 3931.33 | P22: 4308.88 | Q22: 4564.53
C23: EBIT | H23: =H20-H22 -> -358.44 | I23: =I20-I22 -> 3491.31 | J23: =J20-J22 -> 4680.66 | K23: =K20-K22 -> 3049.9 | L23: =L20-L22 -> 7395.07 | M23: =M20-M22 -> 10671.91 | N23: =N20-N22 -> 11008.2 | O23: =O20-O22 -> 24179.6 | ... Q23: =Q20-Q22 -> 18866.34
C25: Interest | H25: 5901.73 | I25: 5570.23 | J25: 5656.52 | K25: 5314.82 | L25: 5106.33 | M25: 4094.78 | N25: 3333.5 | O25: 3388.09 | P25: 3339.79 | Q25: 3366.83
C26: EBT | H26: =H23-H25 -> -6260.17 | I26: =I23-I25 -> -2078.92 | J26: =J23-J25 -> -975.86 | K26: =K23-K25 -> -2264.92 | L26: =L23-L25 -> 2288.74 | M26: =M23-M25 -> 6577.13 | N26: =N23-N25 -> 7674.7 | O26: =O23-O25 -> 20791.51 | ... Q26: =Q23-Q25 -> 15499.51
C28: Tax | H28: -86.07 | I28: -5.15 | J28: 8.54 | K28: 9.85 | L28: 1018.76 | M28: 1665.55 | N28: -3051.94 | O28: -37.28 | P28: 3609.9 | Q28: 2528.43
C30: Net Profit | H30: =H26-H28 -> -6174.1 | I30: =I26-I28 -> -2073.77 | J30: =J26-J28 -> -984.4 | K30: =K26-K28 -> -2274.77 | L30: =L26-L28 -> 1269.98 | M30: =M26-M28 -> 4911.58 | N30: =N26-N28 -> 10726.64 | O30: =O26-O28 -> 20828.79 | ... Q30: =Q26-Q28 -> 12971.08
B34: =B1 -> Adani Power
A35: =A2 -> # | B35: Balance Sheet
B36: =B3 -> (₹ Crore)
H37: =H5 -> 2017 | I37: =I5 -> 2018 | J37: =J5 -> 2019 | K37: =K5 -> 2020 | L37: =L5 -> 2021 | M37: =M5 -> 2022 | N37: =N5 -> 2023 | O37: =O5 -> 2024 | ... Q37: =Q5 -> 2026
B39: ASSETS
C40: Inventories | H40: 1760.41 | I40: 873.98 | J40: 1224.08 | K40: 2522.77 | L40: 2025.11 | M40: 2258.27 | N40: 3075.2 | O40: 4142.1 | P40: 3317.28 | Q40: 3623.48
C42: Receivables over 6m | H42: 0 | I42: 0 | J42: 0 | K42: 0 | L42: 0 | M42: 0 | N42: 0 | O42: 5644 | P42: 6551 | Q42: 4617
C43: Receivables under 6m | H43: 7704 | I43: 6070 | J43: 8551 | K43: 8366 | L43: 11438 | M43: 9561 | N43: 11529 | O43: 6033 | P43: 6471 | Q43: 7175
C44: Prov for Doubtful | H44: 0 | I44: 0 | J44: 0 | K44: 0 | L44: 0 | M44: 0 | N44: 0 | O44: 0 | P44: 0 | Q44: 0
C45: Total Trade receivables | H45: =SUM(H42:H44) -> 7704 | I45: =SUM(I42:I44) -> 6070 | J45: =SUM(J42:J44) -> 8551 | K45: =SUM(K42:K44) -> 8366 | L45: =SUM(L42:L44) -> 11438 | M45: =SUM(M42:M44) -> 9561 | N45: =SUM(N42:N44) -> 11529 | O45: =SUM(O42:O44) -> 11677 | ... Q45: =SUM(Q42:Q44) -> 11792
C47: Cash Equivalents | H47: 604.17 | I47: 856.61 | J47: 915.88 | K47: 1979.31 | L47: 1607.32 | M47: 2364.68 | N47: 1873.65 | O47: 7211.76 | P47: 6119.88 | Q47: 6926.32
C48: Loans n Advances | H48: 771 | I48: 752 | J48: 659 | K48: 880 | L48: 909 | M48: 1474 | N48: 1802 | O48: 1242 | P48: 1057 | Q48: 1479
C49: Other asset items | H49: 5991 | I49: 8719 | J49: 5863 | K49: 3081 | L49: 3245 | M49: 2596 | N49: 2556 | O49: 3421 | P49: 6902 | Q49: 11677
C51: Total Current Assets | H51: =H40+H45+SUM(H47:H49) -> 16830.58 | I51: =I40+I45+SUM(I47:I49) -> 17271.59 | J51: =J40+J45+SUM(J47:J49) -> 17212.96 | K51: =K40+K45+SUM(K47:K49) -> 16829.08 | L51: =L40+L45+SUM(L47:L49) -> 19224.43 | M51: =M40+M45+SUM(M47:M49) -> 18253.95 | N51: =N40+N45+SUM(N47:N49) -> 20835.85 | O51: =O40+O45+SUM(O47:O49) -> 27693.86 | ... Q51: =Q40+Q45+SUM(Q47:Q49) -> 35497.8
C53: Land | H53: 228 | I53: 275 | J53: 821 | K53: 797 | L53: 874 | M53: 1017 | N53: 1085 | O53: 2076 | P53: 4103 | Q53: 4214
C54: Building | H54: 1409 | I54: 1476 | J54: 1497 | K54: 2415 | L54: 1725 | M54: 1633 | N54: 1900 | O54: 2158 | P54: 2978 | Q54: 3200
C55: Plant Machinery | H55: 58202 | I55: 58515 | J55: 58967 | K55: 65724 | L55: 66252 | M55: 69592 | N55: 69793 | O55: 85315 | P55: 92737 | Q55: 96779
C56: Equipments | H56: 45 | I56: 45 | J56: 45 | K56: 49 | L56: 56 | M56: 69 | N56: 86 | O56: 104 | P56: 124 | Q56: 151
...

Sheet Assumptions
B1: =Cover!B11 -> Adani Power
B2: Inputs and Assumptions
C4: GENERAL | J4: EQUITY
C8: - | D8: First Year of Forecast in Financial Model: | H8: 2027 | J8: - | K8: Stock Price - 25/9/26 | O8: 202.71
C9: - | D9: Scenarios : | J9: - | K9: ="Fully Diluted Shares O/S (Cr) - Dec. 31, "&H8-1 -> Fully Diluted Shares O/S (Cr) - Dec. 31, 2026 | O9: =19284694705/10000000 -> 1928.4695
D10: CAPACITY SCENARIOS - Capacity Commissioned, Plant Availability | J10: - | K10: Face value | O10: 2
D11: TARIFF SCENARIO - New-PPA Capacity Charge, Merchant Tariff | J11: - | K11: Book value per share | O11: ='Historical Data'!Q91/Assumptions!O9 -> 33.672755
D12: ECONOMIC SCENARIOS - Cost of Incremental Debt, Cost Inflation | J12: - | K12: EPS | O12: ='Historical Data'!Q30/Assumptions!O9 -> 6.7261008
C13: - | D13: Terminal Growth Rate | H13: 0.0456
C16: INSTALLED CAPACITY | J16: OPERATING PARAMETERS
C20: Fiscal Year | E20: Capacity added (MW) | G20: Cumulative (MW) | J20: Parameter
C21: =$H$8-1 -> 2026 | E21: - | G21: 18150 | J21: - | K21: Plant Availability | O21: 0.9
C22: =C21+1 -> 2027 | E22: 2920 | G22: =G21+E22 -> 21070 | J22: - | K22: Plant Load Factor (PLF) | O22: 0.68
C23: =C22+1 -> 2028 | E23: 2400 | G23: =G22+E23 -> 23470 | J23: - | K23: Auxiliary power consumption | O23: 0.06
C24: =C23+1 -> 2029 | E24: 2400 | G24: =G23+E24 -> 25870 | J24: - | K24: Contracted capacity | O24: 0.96
C25: =C24+1 -> 2030 | E25: 8000 | G25: =G24+E25 -> 33870 | J25: - | K25: Legacy capacity charge | O25: 2.6
C26: =C25+1 -> 2031 | E26: 5600 | G26: =G25+E26 -> 39470 | J26: - | K26: New-PPA capacity charge — tied 13,320 MW | O26: 4.11
C27: =C26+1 -> 2032 | E27: 2400 | G27: =G26+E27 -> 41870 | J27: - | K27: New-PPA capacity charge — untied 10,400 MW | O27: 4.2
J28: - | K28: Capacity-charge escalation | O28: 0.02
J29: - | K29: Merchant tariff | O29: 5.2
C32: COST | J32: DEPRECIATION
C36: - | D36: Electricity Generation | H36: =(((G21*O60)*O58*(O22-0.01))-((G21*O60)*O58*(O22-0.01)*O23))/10000 -> 9913.3077 | J36: - | K36: Depreciation Methodology Used: | O36: Straight Line
C37: - | D37: Fuel Cost | H37: ='Historical Data'!Q11/H36 -> 2.9423096 | J37: - | K37: Years remaining for depreciation of existing assets: | O37: ='Historical Data'!Q66/'Historical Data'!Q22 -> 15.204514
C38: - | D38: Coal cost inflation / Other income growth | H38: 0.03 | J38: - | K38: Years used for depreciation of new assets: | O38: 25
C41: TAXES | J41: INTEREST RATE
C45: - | D45: Tax rate assumed in the Model: | H45: 0.25168 | J45: - | K45: Interest earned on cash balances | O45: 0.065
J46: - | K46: Interest rate on bank revolver / working capital | O46: 0.068
J47: - | K47: Interest rate on senior secured term debt | O47: 0.085
C50: CAPEX & CWIP | J50: Extended - OPERATING PARAMETERS
C54: - | D54: Total capex program | H54: 202000 | J54: Parameter
C55: - | D55: Capex per MW — blended | H55: 8.4 | J55: - | K55: Pipeline — PSA tied | O55: 13320
C56: - | D56: Capex per MW — greenfield | H56: 10 | J56: - | K56: Pipeline — total | O56: 23720
C57: - | D57: Opening CWIP | H57: ='Historical Data'!Q68 -> 35053.46 | J57: - | K57: Tied share of additions | O57: =O55/O56 -> 0.56155143
C58: - | D58: Maintenance capex per MW | H58: 0.05 | J58: - | K58: Hours per year | O58: =24*365 -> 8760
C59: S-curve weights | J59: - | K59: Normative availability | O59: 0.85
C60: - | D60: Year T−3 | H60: 0.15 | J60: - | K60: Effective capacity factor | O60: 0.99
C61: - | D61: Year T−2 | H61: 0.35
C62: - | D62: Year T−1 | H62: 0.35
C63: - | D63: Year T (COD) | H63: 0.15
C66: ADJUSTMENT | J66: WORKING CAPITAL DAYS
...

Sheet Comp Data
B1: =Cover!B11 -> Adani Power
B2: Comparable Company Data
B5: S.No. | C5: Company | E5: CMP | F5: No. Eq. Shares | G5: Debt | H5: Cash | I5: Net Debt | J5: Mar Cap | K5: EV | L5: Sales | M5: EBITDA | N5: PAT 12M Rs.Cr.
B6: 1 | C6: NTPC | E6: 325.9 | F6: 969.67 | G6: 271004.58 | H6: 8003.78 | I6: =G6-H6 -> 263000.8 | J6: 316014.36 | K6: 579015.16 | L6: 191058.77 | M6: 60059.41 | N6: 27762.97
B7: =B6+1 -> 2 | C7: Tata Power Co. | E7: 366.05 | F7: 319.53 | G7: 76141.27 | H7: 13644 | I7: =G7-H7 -> 62497.27 | J7: 116965.4 | K7: 179462.67 | L7: 63444.78 | M7: 17228.43 | N7: 3915.45
B8: =B7+1 -> 3 | C8: JSW Energy | E8: 514.2 | F8: 183.35 | G8: 76945.78 | H8: 5765.22 | I8: =G8-H8 -> 71180.56 | J8: 94277.69 | K8: 165458.25 | L8: 18964.89 | M8: 11097.94 | N8: 2006.08
B9: =B8+1 -> 4 | C9: Torrent Power | E9: 1250 | F9: 50.39 | G9: 13970.56 | H9: 831.43 | I9: =G9-H9 -> 13139.13 | J9: 62987.94 | K9: 76127.07 | L9: 29184.09 | M9: 5894.85 | N9: 2323.84
B10: =B9+1 -> 5 | C10: CESC | E10: 141.75 | F10: 132.56 | G10: 21670.57 | H10: 5572.03 | I10: =G10-H10 -> 16098.54 | J10: 18789.96 | K10: 34888.5 | L10: 18853 | M10: 4676 | N10: 1554

Sheet Model >>

Sheet Scenarios
B1: =Cover!B11 -> Adani Power
B2: Capacity, Tariff and Economic Scenario
B5: SCENARIO SWITCH: | D5: 1 | G5: =Assumptions!H8 -> 2027 | H5: =G5+1 -> 2028 | I5: =H5+1 -> 2029 | J5: =I5+1 -> 2030 | K5: =J5+1 -> 2031 | L5: =K5+1 -> 2032 | M5: =L5+1 -> 2033
B9: CAPACITY SCENARIOS | G9: CHOOSE / OFFSET / INDEX
B11: Capacity Commissioned (MW) | G11: {=INDEX(G13:G15,$D$5)} -> 2920 | H11: {=INDEX(H13:H15,$D$5)} -> 2400 | I11: {=INDEX(I13:I15,$D$5)} -> 2400 | J11: {=INDEX(J13:J15,$D$5)} -> 8000 | K11: {=INDEX(K13:K15,$D$5)} -> 5600 | L11: {=INDEX(L13:L15,$D$5)} -> 2400 | M11: 0
C13: Base Case | G13: =Assumptions!E22 -> 2920 | H13: =Assumptions!E23 -> 2400 | I13: =Assumptions!E24 -> 2400 | J13: =Assumptions!E25 -> 8000 | K13: =Assumptions!E26 -> 5600 | L13: =Assumptions!E27 -> 2400 | M13: 0
C14: Best Case | G14: 2920 | H14: 2400 | I14: 2400 | J14: 8000 | K14: 5600 | L14: 2400 | M14: 0
C15: Worst Case | G15: 1600 | H15: 3720 | I15: 2400 | J15: 4000 | K15: 5600 | L15: 4400 | M15: 2000
B17: Plant Availability (%) | G17: {=INDEX(G19:G21,$D$5)} -> 0.9 | H17: {=INDEX(H19:H21,$D$5)} -> 0.9 | I17: {=INDEX(I19:I21,$D$5)} -> 0.905 | J17: {=INDEX(J19:J21,$D$5)} -> 0.905 | K17: {=INDEX(K19:K21,$D$5)} -> 0.91 | L17: {=INDEX(L19:L21,$D$5)} -> 0.91
C19: =C13 -> Base Case | G19: =Assumptions!O21 -> 0.9 | H19: 0.9 | I19: 0.905 | J19: 0.905 | K19: 0.91 | L19: 0.91
C20: =C14 -> Best Case | G20: 0.91 | H20: 0.915 | I20: 0.92 | J20: 0.92 | K20: 0.925 | L20: 0.925
C21: =C15 -> Worst Case | G21: 0.88 | H21: 0.875 | I21: 0.87 | J21: 0.87 | K21: 0.87 | L21: 0.87
B25: TARIFF SCENARIOS
B27: New-PPA Capacity Charge — untied capacity (₹/kWh) | G27: {=INDEX(G29:G31,$D$5)} -> 4.2 | H27: {=INDEX(H29:H31,$D$5)} -> 4.284 | I27: {=INDEX(I29:I31,$D$5)} -> 4.36968 | J27: {=INDEX(J29:J31,$D$5)} -> 4.4570736 | K27: {=INDEX(K29:K31,$D$5)} -> 4.5462151 | L27: {=INDEX(L29:L31,$D$5)} -> 4.6371394
C29: =C19 -> Base Case | G29: =Assumptions!O27 -> 4.2 | H29: =G29*(1+Assumptions!$O$28) -> 4.284 | I29: =H29*(1+Assumptions!$O$28) -> 4.36968 | J29: =I29*(1+Assumptions!$O$28) -> 4.4570736 | K29: =J29*(1+Assumptions!$O$28) -> 4.5462151 | L29: =K29*(1+Assumptions!$O$28) -> 4.6371394
A30: 0.07 | C30: =C20 -> Best Case | G30: =G29*(1+$A30) -> 4.494 | H30: =H29*(1+$A30) -> 4.58388 | I30: =I29*(1+$A30) -> 4.6755576 | J30: =J29*(1+$A30) -> 4.7690688 | K30: =K29*(1+$A30) -> 4.8644501 | L30: =L29*(1+$A30) -> 4.9617391
A31: -0.07 | C31: =C21 -> Worst Case | G31: =G29*($A$31+1) -> 3.906 | H31: =H29*($A$31+1) -> 3.98412 | I31: =I29*($A$31+1) -> 4.0638024 | J31: =J29*($A$31+1) -> 4.1450784 | K31: =K29*($A$31+1) -> 4.22798 | L31: =L29*($A$31+1) -> 4.3125396
B34: Merchant Tariff (₹/kWh) | G34: =OFFSET(G35,$D$5,0) -> 5.2 | H34: =OFFSET(H35,$D$5,0) -> 5.15 | I34: =OFFSET(I35,$D$5,0) -> 5.1 | J34: =OFFSET(J35,$D$5,0) -> 5.05 | K34: =OFFSET(K35,$D$5,0) -> 5 | L34: =OFFSET(L35,$D$5,0) -> 5
C36: =C13 -> Base Case | G36: =Assumptions!O29 -> 5.2 | H36: 5.15 | I36: 5.1 | J36: 5.05 | K36: 5 | L36: 5
C37: =C14 -> Best Case | G37: 6 | H37: 6 | I37: 5.9 | J37: 5.9 | K37: 5.8 | L37: 5.8
C38: =C15 -> Worst Case | G38: 4.5 | H38: 4.4 | I38: 4.3 | J38: 4.25 | K38: 4.2 | L38: 4.2
B42: ECONOMIC SCENARIOS
B44: Cost of Incremental Debt (%) | G44: {=INDEX(G46:G48,$D$5)} -> 0.085 | H44: {=INDEX(H46:H48,$D$5)} -> 0.085 | I44: {=INDEX(I46:I48,$D$5)} -> 0.085 | J44: {=INDEX(J46:J48,$D$5)} -> 0.085 | K44: {=INDEX(K46:K48,$D$5)} -> 0.085 | L44: {=INDEX(L46:L48,$D$5)} -> 0.085
C46: =C36 -> Base Case | G46: 0.085 | H46: 0.085 | I46: 0.085 | J46: 0.085 | K46: 0.085 | L46: 0.085
C47: =C37 -> Best Case | G47: 0.0825 | H47: 0.08 | I47: 0.08 | J47: 0.0775 | K47: 0.0775 | L47: 0.0775
C48: =C38 -> Worst Case | G48: 0.09 | H48: 0.0925 | I48: 0.095 | J48: 0.095 | K48: 0.0975 | L48: 0.0975
B51: Cost Inflation (%) — fixed O&M only | G51: =OFFSET(G52,$D$5,0) -> 0.05 | H51: =OFFSET(H52,$D$5,0) -> 0.0475 | I51: =OFFSET(I52,$D$5,0) -> 0.0475 | J51: =OFFSET(J52,$D$5,0) -> 0.045 | K51: =OFFSET(K52,$D$5,0) -> 0.045 | L51: =OFFSET(L52,$D$5,0) -> 0.045
C53: =C46 -> Base Case | G53: 0.05 | H53: 0.0475 | I53: 0.0475 | J53: 0.045 | K53: 0.045 | L53: 0.045
C54: =C47 -> Best Case | G54: 0.045 | H54: 0.0425 | I54: 0.0425 | J54: 0.04 | K54: 0.04 | L54: 0.04
C55: =C48 -> Worst Case | G55: 0.06 | H55: 0.0575 | I55: 0.0575 | J55: 0.055 | K55: 0.055 | L55: 0.055
B59: DCF SCENARIO
B61: WACC (%) | G61: {=INDEX(G63:G65,$D$5)} -> 0.086480245 | H61: {=INDEX(H63:H65,$D$5)} -> 0.088980245 | I61: {=INDEX(I63:I65,$D$5)} -> 0.091480245 | J61: {=INDEX(J63:J65,$D$5)} -> 0.093980245 | K61: {=INDEX(K63:K65,$D$5)} -> 0.096480245
C63: =C53 -> Base Case | G63: =H63-0.25% -> 0.086480245 | H63: =I63-0.25% -> 0.088980245 | I63: =WACC!G48 -> 0.091480245 | J63: =I63+0.25% -> 0.093980245 | K63: =J63+0.25% -> 0.096480245
C64: =C54 -> Best Case | G64: =H64-0.25% -> 0.076480245 | H64: =I64-0.25% -> 0.078980245 | I64: =I63-1% -> 0.081480245 | J64: =I64+0.25% -> 0.083980245 | K64: =J64+0.25% -> 0.086480245
C65: =C55 -> Worst Case | G65: =H65-0.25% -> 0.096480245 | H65: =I65-0.25% -> 0.098980245 | I65: =I63+1% -> 0.10148025 | J65: =I65+0.25% -> 0.10398025 | K65: =J65+0.25% -> 0.10648025
B68: Terminal Growth Rate (%) | G68: {=INDEX(G70:G72,$D$5)} -> 0.04 | H68: {=INDEX(H70:H72,$D$5)} -> 0.0425 | I68: {=INDEX(I70:I72,$D$5)} -> 0.045 | J68: {=INDEX(J70:J72,$D$5)} -> 0.0475 | K68: {=INDEX(K70:K72,$D$5)} -> 0.05
C70: =C63 -> Base Case | G70: 0.04 | H70: 0.0425 | I70: 0.045 | J70: 0.0475 | K70: 0.05
C71: =C64 -> Best Case | G71: 0.045 | H71: 0.0475 | I71: 0.05 | J71: 0.0525 | K71: 0.055
C72: =C65 -> Worst Case | G72: 0.03 | H72: 0.0325 | I72: 0.035 | J72: 0.0375 | K72: 0.04

Sheet Model
P1: =UPPER("CURRENTLY RUNNING: " & CHOOSE(Scenarios!D5,Scenarios!C13,Scenarios!C14,Scenarios!C15) & " Scenario") -> CURRENTLY RUNNING: BASE CASE SCENARIO
B2: =Cover!B11 -> Adani Power
B3: Capacity & Commissioning Schedule
B5: (MW)
K6: Projected
H7: =I7-1 -> 2024 | I7: =J7-1 -> 2025 | J7: =K7-1 -> 2026 | K7: =Assumptions!H8 -> 2027 | L7: =K7+1 -> 2028 | M7: =L7+1 -> 2029 | N7: =M7+1 -> 2030 | O7: =N7+1 -> 2031 | P7: =O7+1 -> 2032
B8: Installed Capacity
C9: Capacity commissioned | F9: (MW) | J9: 0 | K9: =Scenarios!G11 -> 2920 | L9: =Scenarios!H11 -> 2400 | M9: =Scenarios!I11 -> 2400 | N9: =Scenarios!J11 -> 8000 | O9: =Scenarios!K11 -> 5600 | P9: =Scenarios!L11 -> 2400
C10: Cumulative capacity | F10: (MW) | J10: =Assumptions!G21 -> 18150 | K10: =J10+K9 -> 21070 | L10: =K10+L9 -> 23470 | M10: =L10+M9 -> 25870 | N10: =M10+N9 -> 33870 | O10: =N10+O9 -> 39470 | P10: =O10+P9 -> 41870
C11: Effective capacity | F11: (MW) | J11: 18000 | K11: =J10+(K9/2) -> 19610 | L11: =K10+(L9/2) -> 22270 | M11: =L10+(M9/2) -> 24670 | N11: =M10+(N9/2) -> 29870 | O11: =N10+(O9/2) -> 36670 | P11: =O10+(P9/2) -> 40670
B14: Operating Parameters
C15: Plant availability | F15: (%) | J15: 0.89 | K15: =Scenarios!G17 -> 0.9 | L15: =Scenarios!H17 -> 0.9 | M15: =Scenarios!I17 -> 0.905 | N15: =Scenarios!J17 -> 0.905 | O15: =Scenarios!K17 -> 0.91 | P15: =Scenarios!L17 -> 0.91
C16: Plant load factor | F16: (%) | J16: 0.67 | K16: =Assumptions!$O$22 -> 0.68 | L16: =Assumptions!$O$22 -> 0.68 | M16: =Assumptions!$O$22 -> 0.68 | N16: =Assumptions!$O$22 -> 0.68 | O16: =Assumptions!$O$22 -> 0.68 | P16: =Assumptions!$O$22 -> 0.68
C17: Auxiliary consumption | F17: (%) | J17: =Assumptions!$O$23 -> 0.06 | K17: =Assumptions!$O$23 -> 0.06 | L17: =Assumptions!$O$23 -> 0.06 | M17: =Assumptions!$O$23 -> 0.06 | N17: =Assumptions!$O$23 -> 0.06 | O17: =Assumptions!$O$23 -> 0.06 | P17: =Assumptions!$O$23 -> 0.06
C18: Contracted capacity | F18: (%) | J18: 0.95 | K18: =Assumptions!$O$24 -> 0.96 | L18: =Assumptions!$O$24 -> 0.96 | M18: =Assumptions!$O$24 -> 0.96 | N18: =Assumptions!$O$24 -> 0.96 | O18: =Assumptions!$O$24 -> 0.96 | P18: =Assumptions!$O$24 -> 0.96
B21: Capacity by Vintage
C22: Tied additions | F22: (MW) | J22: 0 | K22: =K9*Assumptions!$O$57 -> 1639.7302 | L22: =L9*Assumptions!$O$57 -> 1347.7234 | M22: =M9*Assumptions!$O$57 -> 1347.7234 | N22: =N9*Assumptions!$O$57 -> 4492.4115 | O22: =O9*Assumptions!$O$57 -> 3144.688 | P22: =P9*Assumptions!$O$57 -> 1347.7234
C23: Untied additions | F23: (MW) | J23: 0 | K23: =K9-K22 -> 1280.2698 | L23: =L9-L22 -> 1052.2766 | M23: =M9-M22 -> 1052.2766 | N23: =N9-N22 -> 3507.5885 | O23: =O9-O22 -> 2455.312 | P23: =P9-P22 -> 1052.2766
C25: Legacy — cumulative | F25: (MW) | J25: =J10 -> 18150 | K25: =J25 -> 18150 | L25: =K25 -> 18150 | M25: =L25 -> 18150 | N25: =M25 -> 18150 | O25: =N25 -> 18150 | P25: =O25 -> 18150
C26: New tied — cumulative | F26: (MW) | J26: 0 | K26: =J26+K22 -> 1639.7302 | L26: =K26+L22 -> 2987.4536 | M26: =L26+M22 -> 4335.1771 | N26: =M26+N22 -> 8827.5885 | O26: =N26+O22 -> 11972.277 | P26: =O26+P22 -> 13320
C27: New untied — cumulative | F27: (MW) | J27: 0 | K27: =J27+K23 -> 1280.2698 | L27: =K27+L23 -> 2332.5464 | M27: =L27+M23 -> 3384.8229 | N27: =M27+N23 -> 6892.4115 | O27: =N27+O23 -> 9347.7234 | P27: =O27+P23 -> 10400
C29: Legacy — effective | F29: (MW) | J29: =J11 -> 18000 | K29: =K25 -> 18150 | L29: =L25 -> 18150 | M29: =M25 -> 18150 | N29: =N25 -> 18150 | O29: =O25 -> 18150 | P29: =P25 -> 18150
C30: New tied — effective | F30: (MW) | J30: 0 | K30: =J26+(K22/2) -> 819.86509 | L30: =K26+(L22/2) -> 2313.5919 | M30: =L26+(M22/2) -> 3661.3153 | N30: =M26+(N22/2) -> 6581.3828 | O30: =N26+(O22/2) -> 10399.933 | P30: =O26+(P22/2) -> 12646.138
C31: New untied — effective | F31: (MW) | J31: 0 | K31: =J27+(K23/2) -> 640.13491 | L31: =K27+(L23/2) -> 1806.4081 | M31: =L27+(M23/2) -> 2858.6847 | N31: =M27+(N23/2) -> 5138.6172 | O31: =N27+(O23/2) -> 8120.0675 | P31: =O27+(P23/2) -> 9873.8617
C33: Check: total effective | K33: =ROUND(SUM(K29:K31) - K11, 1) -> 0 | L33: =ROUND(SUM(L29:L31) - L11, 1) -> 0 | M33: =ROUND(SUM(M29:M31) - M11, 1) -> 0 | N33: =ROUND(SUM(N29:N31) - N11, 1) -> 0 | O33: =ROUND(SUM(O29:O31) - O11, 1) -> 0 | P33: =ROUND(SUM(P29:P31) - P11, 1) -> 0
P36: =P1 -> CURRENTLY RUNNING: BASE CASE SCENARIO
B37: =B2 -> Adani Power
B38: Revenue Schedule
B40: (₹ Crore)
K41: =K6 -> Projected
H42: =H7 -> 2024 | I42: =I7 -> 2025 | J42: =J7 -> 2026 | K42: =K7 -> 2027 | L42: =L7 -> 2028 | M42: =M7 -> 2029 | N42: =N7 -> 2030 | O42: =O7 -> 2031 | P42: =P7 -> 2032
B43: VOLUMES
C44: Gross generation — legacy | F44: (cr kWh) | J44: =(J29*Assumptions!$O$58*Model!J16)/10000 -> 10564.56 | K44: =(K29*Assumptions!$O$58*Model!K16)/10000 -> 10811.592 | L44: =(L29*Assumptions!$O$58*Model!L16)/10000 -> 10811.592 | M44: =(M29*Assumptions!$O$58*Model!M16)/10000 -> 10811.592 | N44: =(N29*Assumptions!$O$58*Model!N16)/10000 -> 10811.592 | O44: =(O29*Assumptions!$O$58*Model!O16)/10000 -> 10811.592 | P44: =(P29*Assumptions!$O$58*Model!P16)/10000 -> 10811.592
C45: Less: Auxiliary consumption | F45: (cr kWh) | J45: =-J44*J17 -> -633.8736 | K45: =-K44*K17 -> -648.69552 | L45: =-L44*L17 -> -648.69552 | M45: =-M44*M17 -> -648.69552 | N45: =-N44*N17 -> -648.69552 | O45: =-O44*O17 -> -648.69552 | P45: =-P44*P17 -> -648.69552
C46: Net saleable — legacy | F46: (cr kWh) | J46: =J44+J45 -> 9930.6864 | K46: =K44+K45 -> 10162.896 | L46: =L44+L45 -> 10162.896 | M46: =M44+M45 -> 10162.896 | N46: =N44+N45 -> 10162.896 | O46: =O44+O45 -> 10162.896 | P46: =P44+P45 -> 10162.896
C48: PPA units — legacy | F48: (cr kWh) | J48: =J46*J18 -> 9434.1521 | K48: =K46*K18 -> 9756.3806 | L48: =L46*L18 -> 9756.3806 | M48: =M46*M18 -> 9756.3806 | N48: =N46*N18 -> 9756.3806 | O48: =O46*O18 -> 9756.3806 | P48: =P46*P18 -> 9756.3806
C49: Merchant units — legacy | F49: (cr kWh) | J49: =J46-J48 -> 496.53432 | K49: =K46-K48 -> 406.51586 | L49: =L46-L48 -> 406.51586 | M49: =M46-M48 -> 406.51586 | N49: =N46-N48 -> 406.51586 | O49: =O46-O48 -> 406.51586 | P49: =P46-P48 -> 406.51586
C51: Billable capacity — new tied | F51: (cr kWh) | J51: =(J30*Assumptions!$O$58*Assumptions!$O$59)/10000 -> 0 | K51: =(K30*Assumptions!$O$58*Assumptions!$O$59)/10000 -> 610.47155 | L51: =(L30*Assumptions!$O$58*Assumptions!$O$59)/10000 -> 1722.7005 | M51: =(M30*Assumptions!$O$58*Assumptions!$O$59)/10000 -> 2726.2154 | N51: =(N30*Assumptions!$O$58*Assumptions!$O$59)/10000 -> 4900.4976 | O51: =(O30*Assumptions!$O$58*Assumptions!$O$59)/10000 -> 7743.7898 | P51: =(P30*Assumptions!$O$58*Assumptions!$O$59)/10000 -> 9416.3146
C52: Billable capacity — new untied | F52: (cr kWh) | J52: =(J31*Assumptions!$O$58*Assumptions!$O$59)/10000 -> 0 | K52: =(K31*Assumptions!$O$58*Assumptions!$O$59)/10000 -> 476.64445 | L52: =(L31*Assumptions!$O$58*Assumptions!$O$59)/10000 -> 1345.0515 | M52: =(M31*Assumptions!$O$58*Assumptions!$O$59)/10000 -> 2128.5766 | N52: =(N31*Assumptions!$O$58*Assumptions!$O$59)/10000 -> 3826.2144 | O52: =(O31*Assumptions!$O$58*Assumptions!$O$59)/10000 -> 6046.2022 | P52: =(P31*Assumptions!$O$58*Assumptions!$O$59)/10000 -> 7352.0774
C53: Net saleable — new | F53: (cr kWh) | J53: =((J30+J31)*Assumptions!$O$58*Model!J16*(1-Model!J17))/10000 -> 0 | K53: =(K30+K31)*Assumptions!$O$58*Model!K16*(1-Model!K17)/10000 -> 817.51123 | L53: =(L30+L31)*Assumptions!$O$58*Model!L16*(1-Model!L17)/10000 -> 2306.9495 | M53: =(M30+M31)*Assumptions!$O$58*Model!M16*(1-Model!M17)/10000 -> 3650.8036 | N53: =(N30+N31)*Assumptions!$O$58*Model!N16*(1-Model!N17)/10000 -> 6562.4874 | O53: =(O30+O31)*Assumptions!$O$58*Model!O16*(1-Model!O17)/10000 -> 10370.074 | P53: =(P30+P31)*Assumptions!$O$58*Model!P16*(1-Model!P17)/10000 -> 12609.831
...

Sheet DCF>>

Sheet WACC
B1: =Cover!B11 -> Adani Power
B2: WACC
J5: Debt / | K5: Debt / | L5: Levered | M5: Unlevered
B6: Name of the Company | F6: Country | G6: Total Debt (Cr) | H6: Total Equity (Cr) | I6: Tax rate1 | J6: Equity | K6: Capital | L6: Beta2 | M6: Beta3
B10: Adani Power | F10: India | G10: =Model!J240+Model!J245+Model!J247 -> 54671 | H10: =Model!J255 -> 64936.88 | I10: 0.2517 | J10: =G10/H10 -> 0.84190987 | K10: =G10/(G10+H10) -> 0.45708527 | L10: =Beta!J14 -> 1.1923462 | M10: =L10/(1+(1-I10)*J10) -> 0.73150024
B11: NTPC | F11: India | G11: 271004.58 | H11: =G11/J11 -> 203762.84 | I11: 0.2517 | J11: 1.33 | K11: =G11/(H11+G11) -> 0.57081545 | L11: =NTPC!J14 -> 0.86462711 | M11: =L11/(1+(1-I11)*J11) -> 0.43334513
B12: Tata Power Co. | F12: India | G12: 76141.27 | H12: =G12/J12 -> 39451.435 | I12: 0.2517 | J12: 1.93 | K12: =G12/(H12+G12) -> 0.65870307 | L12: ='Tata Power'!J14 -> 1.2074572 | M12: =L12/(1+(1-I12)*J12) -> 0.49400533
B13: JSW Energy | F13: India | G13: 76945.78 | H13: =G13/J13 -> 30778.312 | I13: 0.2517 | J13: 2.5 | K13: =G13/(H13+G13) -> 0.71428571 | L13: ='JSW Energy'!J14 -> 1.0201684 | M13: =L13/(1+(1-I13)*J13) -> 0.35536652
B14: Torrent Power | F14: India | G14: 13970.56 | H14: =G14/J14 -> 19137.753 | I14: 0.2517 | J14: 0.73 | K14: =G14/(H14+G14) -> 0.42196532 | L14: ='Torrent Power'!J14 -> 1.1182002 | M14: =L14/(1+(1-I14)*J14) -> 0.72316488
B15: CESC | F15: India | G15: 21670.57 | H15: =G15/J15 -> 12526.341 | I15: 0.2517 | J15: 1.73 | K15: =G15/(H15+G15) -> 0.63369963 | L15: =CESE!J14 -> 1.032776 | M15: =L15/(1+(1-I15)*J15) -> 0.45009783
H17: Average | I17: =AVERAGE(I11:I15) -> 0.2517 | J17: =AVERAGE(J11:J15) -> 1.644 | K17: =AVERAGE(K11:K15) -> 0.59989384 | L17: =AVERAGE(L11:L15) -> 1.0486458 | M17: =AVERAGE(M11:M15) -> 0.49119594
H18: Median | I18: =MEDIAN(I11:I15) -> 0.2517 | J18: =MEDIAN(J11:J15) -> 1.73 | K18: =MEDIAN(K11:K15) -> 0.63369963 | L18: =MEDIAN(L11:L15) -> 1.032776 | M18: =MEDIAN(M11:M15) -> 0.45009783
B21: Cost of Debt | I21: Cost of Equity
B25: Pre tax cost of Debt | G25: =Scenarios!L44 -> 0.085 | I25: Risk Free Rate | M25: 0.07073
B26: Tax Rate | G26: =Assumptions!H45 -> 0.25168 | I26: Equity Risk Premium | M26: =Rm!G7-WACC!M25 -> 0.058773341
B27: Post Tax Cost of Debt | G27: =G25*(1-G26) -> 0.0636072 | I27: Levered Beta4 | M27: =M38 -> 0.68793349
I28: Cost of Equity | M28: =M25+(M26*M27) -> 0.11116215
B31: Capital Structure | I31: Levered Beta
F35: Current | G35: Target | I35: Peers Median Unlevered Beta | M35: =M18 -> 0.45009783
B36: Total Debt | E36: =G10 -> 54671 | F36: =K10 -> 0.45708527 | G36: ='Ratio Analysis'!N44 -> 0.4138771 | I36: Target Debt / Equity | M36: =G39 -> 0.70612683
B37: Equity | E37: =H10 -> 64936.88 | F37: =1-F36 -> 0.54291473 | G37: =1-G36 -> 0.5861229 | I37: Tax Rate | M37: =G26 -> 0.25168
I38: Levered Beta | M38: =M35*(1+(1-M37)*M36) -> 0.68793349
B39: Debt / Equity | F39: =F36/F37 -> 0.84190987 | G39: =G36/G37 -> 0.70612683
B41: Weighted Average Cost of Capital (WACC)
F45: Total Cost | G45: Total Weight
B46: Debt | F46: =G27 -> 0.0636072 | G46: =G36 -> 0.4138771
B47: Equity | F47: =M28 -> 0.11116215 | G47: =G37 -> 0.5861229
B48: WACC | G48: =(F46*G46)+(F47*G47) -> 0.091480245

Sheet Beta
B1: =Cover!B11 -> Adani Power
B2: Regression Beta - 5Y Weekly
B5: Adani Power Weekly returns | F5: NIFTY Weekly Return | I5: Beta Drifting
B9: Date | C9: Price | D9: Weekly Returns | F9: Price | G9: Return | I9: Levered Raw Beta | J9: =J17 -> 1.2564617
B10: 44458 | C10: 19.17 | D10: 0 | F10: 17853.2 | G10: 0 | I10: Raw Beta Weight | J10: 0.75
B11: 44465 | C11: 19.39 | D11: =C11/C10-1 -> 0.011476265 | F11: 17532.05 | G11: =F11/F10-1 -> -0.017988372 | I11: Market Beta | J11: 1
B12: 44472 | C12: 20.32 | D12: =C12/C11-1 -> 0.047962867 | F12: 17895.2 | G12: =F12/F11-1 -> 0.020713493 | I12: Market Beta Weight | J12: 0.25
B13: 44479 | C13: 22.4 | D13: =C13/C12-1 -> 0.1023622 | F13: 18338.55 | G13: =F13/F12-1 -> 0.0247748
B14: 44486 | C14: 23.41 | D14: =C14/C13-1 -> 0.045089286 | F14: 18114.9 | G14: =F14/F13-1 -> -0.012195621 | I14: Adjusted Beta | J14: =(J9*J10)+(J11*J12) -> 1.1923462
B15: 44493 | C15: 20.1 | D15: =C15/C14-1 -> -0.14139257 | F15: 17671.65 | G15: =F15/F14-1 -> -0.024468807
B16: 44500 | C16: 21.08 | D16: =C16/C15-1 -> 0.048756219 | F16: 17916.8 | G16: =F16/F15-1 -> 0.013872502
B17: 44507 | C17: 21.69 | D17: =C17/C16-1 -> 0.028937381 | F17: 18102.75 | G17: =F17/F16-1 -> 0.010378527 | I17: Beta1 | J17: =J36 -> 1.2564617
B18: 44514 | C18: 20.58 | D18: =C18/C17-1 -> -0.051175657 | F18: 17764.8 | G18: =F18/F17-1 -> -0.018668434
B19: 44521 | C19: 20.25 | D19: =C19/C18-1 -> -0.016034985 | F19: 17026.45 | G19: =F19/F18-1 -> -0.041562528 | I19: SUMMARY OUTPUT
B20: 44528 | C20: 20.16 | D20: =C20/C19-1 -> -0.0044444444 | F20: 17196.7 | G20: =F20/F19-1 -> 0.0099991484
B21: 44535 | C21: 20.81 | D21: =C21/C20-1 -> 0.032242063 | F21: 17511.3 | G21: =F21/F20-1 -> 0.018294208 | I21: Regression Statistics
B22: 44542 | C22: 20.02 | D22: =C22/C21-1 -> -0.037962518 | F22: 16985.2 | G22: =F22/F21-1 -> -0.030043458 | I22: Multiple R | J22: 0.32939894
B23: 44549 | C23: 19.73 | D23: =C23/C22-1 -> -0.014485514 | F23: 17003.75 | G23: =F23/F22-1 -> 0.0010921273 | I23: R Square | J23: 0.10850366
B24: 44556 | C24: 19.94 | D24: =C24/C23-1 -> 0.01064369 | F24: 17354.05 | G24: =F24/F23-1 -> 0.020601338 | I24: Adjusted R Square | J24: 0.10504825
B25: 44563 | C25: 20.04 | D25: =C25/C24-1 -> 0.0050150451 | F25: 17812.7 | G25: =F25/F24-1 -> 0.026428989 | I25: Standard Error | J25: 0.065376334
B26: 44570 | C26: 23.43 | D26: =C26/C25-1 -> 0.16916168 | F26: 18255.75 | G26: =F26/F25-1 -> 0.024872703 | I26: Observations | J26: 260
B27: 44577 | C27: 21.99 | D27: =C27/C26-1 -> -0.061459667 | F27: 17617.15 | G27: =F27/F26-1 -> -0.034980759
B28: 44584 | C28: 21.15 | D28: =C28/C27-1 -> -0.038199181 | F28: 17101.95 | G28: =F28/F27-1 -> -0.029244231 | I28: ANOVA
B29: 44591 | C29: 21.71 | D29: =C29/C28-1 -> 0.026477541 | F29: 17516.3 | G29: =F29/F28-1 -> 0.024228231 | J29: df | K29: SS | L29: MS | M29: F | N29: Significance F
B30: 44598 | C30: 25 | D30: =C30/C29-1 -> 0.15154307 | F30: 17374.75 | G30: =F30/F29-1 -> -0.0080810445 | I30: Regression | J30: 1 | K30: 0.13421024 | L30: 0.13421024 | M30: 31.401076 | N30: 5.3780532e-08
B31: 44605 | C31: 26.32 | D31: =C31/C30-1 -> 0.0528 | F31: 17276.3 | G31: =F31/F30-1 -> -0.0056662686 | I31: Residual | J31: 258 | K31: 1.1027088 | L31: 0.0042740651
B32: 44612 | C32: 24.81 | D32: =C32/C31-1 -> -0.057370821 | F32: 16658.4 | G32: =F32/F31-1 -> -0.03576576 | I32: Total | J32: 259 | K32: 1.236919
B33: 44619 | C33: 23.95 | D33: =C33/C32-1 -> -0.034663442 | F33: 16245.35 | G33: =F33/F32-1 -> -0.024795298
B34: 44626 | C34: 24.36 | D34: =C34/C33-1 -> 0.017118998 | F34: 16630.45 | G34: =F34/F33-1 -> 0.023705245 | J34: Coefficients | K34: Standard Error | L34: t Stat | M34: P-value | N34: Lower 95% | O34: Upper 95% | P34: Lower 95.0% | Q34: Upper 95.0%
B35: 44633 | C35: 25.02 | D35: =C35/C34-1 -> 0.027093596 | F35: 17287.05 | G35: =F35/F34-1 -> 0.039481794 | I35: Intercept | J35: 0.0099154452 | K35: 0.0040627796 | L35: 2.440557 | M35: 0.015337984 | N35: 0.001915014 | O35: 0.017915876 | P35: 0.001915014 | Q35: 0.017915876
B36: 44640 | C36: 28.64 | D36: =C36/C35-1 -> 0.14468425 | F36: 17153 | G36: =F36/F35-1 -> -0.0077543595 | I36: X Variable 1 | J36: 1.2564617 | K36: 0.22422136 | L36: 5.6036663 | M36: 5.3780532e-08 | N36: 0.81492465 | O36: 1.6979987 | P36: 0.81492465 | Q36: 1.6979987
B37: 44647 | C37: 40.69 | D37: =C37/C36-1 -> 0.42074022 | F37: 17670.45 | G37: =F37/F36-1 -> 0.030166735
B38: 44654 | C38: 44.19 | D38: =C38/C37-1 -> 0.08601622 | F38: 17784.35 | G38: =F38/F37-1 -> 0.0064457894
B39: 44661 | C39: 44.65 | D39: =C39/C38-1 -> 0.010409595 | F39: 17475.65 | G39: =F39/F38-1 -> -0.017357958
B40: 44668 | C40: 51.82 | D40: =C40/C39-1 -> 0.16058231 | F40: 17171.95 | G40: =F40/F39-1 -> -0.017378467
B41: 44675 | C41: 56.07 | D41: =C41/C40-1 -> 0.082014666 | F41: 17102.55 | G41: =F41/F40-1 -> -0.0040414746
B42: 44682 | C42: 58.41 | D42: =C42/C41-1 -> 0.041733547 | F42: 16411.25 | G42: =F42/F41-1 -> -0.040420873
B43: 44689 | C43: 50.93 | D43: =C43/C42-1 -> -0.12806026 | F43: 15782.15 | G43: =F43/F42-1 -> -0.03833346
B44: 44696 | C44: 62.45 | D44: =C44/C43-1 -> 0.22619281 | F44: 16266.15 | G44: =F44/F43-1 -> 0.030667558
B45: 44703 | C45: 65.62 | D45: =C45/C44-1 -> 0.050760608 | F45: 16352.45 | G45: =F45/F44-1 -> 0.0053054964
...

Sheet Rm
B1: NIFTY Return - Last 20 Yr
B4: Year | C4: Return
B5: 2025 | C5: 0.1051 | E5: Average Return | G5: {=(PRODUCT(1+C5:C30)^(1/COUNT(C5:C30)))-1} -> 0.11650334
B6: 2024 | C6: 0.0875 | E6: Dividend Yield | G6: 0.013
B7: 2023 | C7: 0.1942 | E7: Total Market Return | G7: =G5+G6 -> 0.12950334
B8: 2022 | C8: 0.0432
B9: 2021 | C9: 0.2412
B10: 2020 | C10: 0.149
B11: 2019 | C11: 0.1202
B12: 2018 | C12: 0.0315
B13: 2017 | C13: 0.2865
B14: 2016 | C14: 0.0301
B15: 2015 | C15: -0.0406
B16: 2014 | C16: 0.3139
B17: 2013 | C17: 0.0676
B18: 2012 | C18: 0.277
B19: 2011 | C19: -0.2462
... B30: 2000 | C30: -0.1465

Sheet Intrinsic Growth
B1: =Cover!B11 -> Adani Power
B4: Calculation of Reinvestment Rate
H6: =Model!K6 -> Projected
G7: =Model!J7 -> 2026 | H7: =Model!K7 -> 2027 | I7: =Model!L7 -> 2028 | J7: =Model!M7 -> 2029 | K7: =Model!N7 -> 2030 | L7: =Model!O7 -> 2031 | M7: =Model!P7 -> 2032
B9: Net Capex | G9: =-Model!K195-Model!K143 -> 27407.871 | H9: =-Model!L195-Model!L143 -> 40051.938 | I9: =-Model!M195-Model!M143 -> 45272.463 | J9: =-Model!N195-Model!N143 -> 32571.775 | K9: =-Model!O195-Model!O143 -> 12710.386 | L9: =-Model!P195-Model!P143 -> 1308.0359 | M9: =-Model!Q195-Model!Q143 -> 0
B10: Changes in Working Capital | G10: =Model!J371 -> -447.11 | H10: =Model!K371 -> -4410.9781 | I10: =Model!L371 -> -6552.8592 | J10: =Model!M371 -> -6313.489 | K10: =Model!N371 -> -13214.518 | L10: =Model!O371 -> -17800.025 | M10: =Model!P371 -> -11561.36
B11: Reinvestment | G11: =G9+G10 -> 26960.761 | H11: =H9+H10 -> 35640.96 | I11: =I9+I10 -> 38719.604 | J11: =J9+J10 -> 26258.286 | K11: =K9+K10 -> -504.13269 | L11: =L9+L10 -> -16491.989 | M11: =M9+M10 -> -11561.36
B13: EBIT | G13: =Model!J153 -> 19446.213 | H13: =Model!K153 -> 23625.494 | I13: =Model!L153 -> 30073.001 | J13: =Model!M153 -> 36241.91 | K13: =Model!N153 -> 49757.344 | L13: =Model!O153 -> 68137.196 | M13: =Model!P153 -> 79534.111
B14: Marginal Tax Rate | G14: =Assumptions!$H$45 -> 0.25168 | H14: =Assumptions!$H$45 -> 0.25168 | I14: =Assumptions!$H$45 -> 0.25168 | J14: =Assumptions!$H$45 -> 0.25168 | K14: =Assumptions!$H$45 -> 0.25168 | L14: =Assumptions!$H$45 -> 0.25168 | M14: =Assumptions!$H$45 -> 0.25168
B15: Post Tax EBIT | G15: =G13*(1-G14) -> 14551.99 | H15: =H13*(1-H14) -> 17679.43 | I15: =I13*(1-I14) -> 22504.228 | J15: =J13*(1-J14) -> 27120.546 | K15: =K13*(1-K14) -> 37234.416 | L15: =L13*(1-L14) -> 50988.426 | M15: =M13*(1-M14) -> 59516.966
B17: Reinvestment Rate | G17: =G11/G15 -> 1.8527199 | H17: =H11/H15 -> 2.0159565 | I17: =I11/I15 -> 1.720548 | J17: =J11/J15 -> 0.9682064 | K17: =K11/K15 -> -0.013539428 | L17: =L11/L15 -> -0.32344574 | M17: =M11/M15 -> -0.19425319
J19: Average Reinvestment Rate | M19: =AVERAGE(G17:M17) -> 0.86088463
J20: Median Reinvestment Rate | M20: =MEDIAN(G17:M17) -> 0.9682064
B22: Calculation of Intrinsic Growth Rate
H24: =H6 -> Projected
G25: =G7 -> 2026 | H25: =H7 -> 2027 | I25: =I7 -> 2028 | J25: =J7 -> 2029 | K25: =K7 -> 2030 | L25: =L7 -> 2031 | M25: =M7 -> 2032
B27: Reinvestment Rate | G27: =G17 -> 1.8527199 | H27: =H17 -> 2.0159565 | I27: =I17 -> 1.720548 | J27: =J17 -> 0.9682064 | K27: =K17 -> -0.013539428 | L27: =L17 -> -0.32344574 | M27: =M17 -> -0.19425319
B28: ROIC | G28: ='Ratio Analysis'!F32 -> 0.091024748 | H28: ='Ratio Analysis'!G32 -> 0.088029704 | I28: ='Ratio Analysis'!H32 -> 0.086218652 | J28: ='Ratio Analysis'!I32 -> 0.082669914 | K28: ='Ratio Analysis'!J32 -> 0.10188157 | L28: ='Ratio Analysis'!K32 -> 0.13899603 | M28: ='Ratio Analysis'!L32 -> 0.16624719
B30: Intrinsic Growth | G30: =G27*G28 -> 0.16864336 | H30: =H27*H28 -> 0.17746405 | I30: =I27*I28 -> 0.14834333 | J30: =J27*J28 -> 0.08004154 | K30: =K27*K28 -> -0.0013794182 | L30: =L27*L28 -> -0.044957672 | M30: =M27*M28 -> -0.032294046
J32: Average Intrinsic Growth | M32: =AVERAGE(G30:M30) -> 0.070837306
J33: Median Intrinsic Growth | M33: =MEDIAN(G30:M30) -> 0.08004154

Sheet DCF
B1: =Cover!B11 -> Adani Power
B2: DCF Valuation
B5: Calculation of PV of FCFF
B7: Terminal Growth Rate | D7: =Scenarios!I68 -> 0.045
B8: WACC | D8: =Scenarios!I61 -> 0.091480245 | H8: =Model!K126 -> Projected
G9: =Model!J127 -> 2026 | H9: =Model!K127 -> 2027 | I9: =Model!L127 -> 2028 | J9: =Model!M127 -> 2029 | K9: =Model!N127 -> 2030 | L9: =Model!O127 -> 2031 | M9: =Model!P127 -> 2032
B11: CFO | G11: =Model!J190 -> 21649.046 | H11: =Model!K190 -> 19356.54 | I11: =Model!L190 -> 25192.708 | J11: =Model!M190 -> 31400.288 | K11: =Model!N190 -> 38730 | L11: =Model!O190 -> 52505.559 | M11: =Model!P190 -> 68373.615
B12: Add: Tax adjusted Interest | G12: =Model!J156*Assumptions!$H$45 -> 847.36377 | H12: =Model!K156*Assumptions!$H$45 -> 844.79773 | I12: =Model!L156*Assumptions!$H$45 -> 1063.6242 | J12: =Model!M156*Assumptions!$H$45 -> 1321.5756 | K12: =Model!N156*Assumptions!$H$45 -> 1550.2616 | L12: =Model!O156*Assumptions!$H$45 -> 1994.9078 | M12: =Model!P156*Assumptions!$H$45 -> 2101.3951
B13: Less: Capex | G13: =Model!J284 -> 23350.09 | H13: =Model!K284 -> 28851.7 | I13: =Model!L284 -> 41769.5 | J13: =Model!M284 -> 47265.5 | K13: =Model!N284 -> 35093.5 | L13: =Model!O284 -> 15945.5 | M13: =Model!P284 -> 5057.5
B14: Free Cash Flow to Firm | G14: =G11+G12-G13 -> -853.68004 | H14: =H11+H12-H13 -> -8650.3623 | I14: =I11+I12-I13 -> -15513.168 | J14: =J11+J12-J13 -> -14543.637 | K14: =K11+K12-K13 -> 5186.7618 | L14: =L11+L12-L13 -> 38554.967 | M14: =M11+M12-M13 -> 65417.51
B16: Mid Year Convention | H16: 0.5 | I16: =H16+1 -> 1.5 | J16: =I16+1 -> 2.5 | K16: =J16+1 -> 3.5 | L16: =K16+1 -> 4.5 | M16: =L16+1 -> 5.5
B17: Discounting Factor | H17: =1/(1+$D$8)^H16 -> 0.95717657 | I17: =1/(1+$D$8)^I16 -> 0.87695272 | J17: =1/(1+$D$8)^J16 -> 0.80345267 | K17: =1/(1+$D$8)^K16 -> 0.73611289 | L17: =1/(1+$D$8)^L16 -> 0.67441705 | M17: =1/(1+$D$8)^M16 -> 0.61789213
B19: PV of FCFF | H19: =H14*H17 -> -8279.9241 | I19: =I14*I17 -> -13604.315 | J19: =J14*J17 -> -11685.124 | K19: =K14*K17 -> 3818.0422 | L19: =L14*L17 -> 26002.127 | M19: =M14*M17 -> 40420.965
B21: Calculation of Terminal Value
B22: FCFF (n+1) | D22: =M14*(1+D7) -> 68361.298
B23: WACC | D23: =D8 -> 0.091480245
B24: Terminal Growth Rate | D24: =D7 -> 0.045
B25: Terminal Value | D25: =D22/(D23-D24) -> 1470760.3
B27: Calculation of Equity Value Per Share | G27: Senstivity Analysis
B28: PV of FCFF | E28: =SUM(H19:M19) -> 36671.771 | M28: =Model!P1 -> CURRENTLY RUNNING: BASE CASE SCENARIO
B29: PV of Terminal Value | E29: =D25*M17 -> 908771.2 | G29: Equity Value Per Share
B30: Enterprise Value | E30: =SUM(E28:E29) -> 945442.97 | I30: WACC
H31: =E37 -> 465.4978 | I31: =Scenarios!G61 -> 0.086480245 | J31: =Scenarios!H61 -> 0.088980245 | K31: =Scenarios!I61 -> 0.091480245 | L31: =Scenarios!J61 -> 0.093980245 | M31: =Scenarios!K61 -> 0.096480245
B32: Add: Cash | E32: =Model!J225 -> 6926.32 | G32: Terminal Growth Rate | H32: =Scenarios!G68 -> 0.04 | I32: 465.4978 | J32: 441.44526 | K32: 419.72882 | L32: 400.0239 | M32: 382.06338
B33: Less: Debt | E33: =Model!J240+Model!J245+Model!J247 -> 54671 | H33: =Scenarios!H68 -> 0.0425 | I33: 492.2848 | J33: 465.4978 | K33: 441.44526 | L33: 419.72882 | M33: 400.0239
B34: Value of Equity | E34: =E30+E32-E33 -> 897698.29 | H34: =Scenarios!I68 -> 0.045 | I34: 522.30069 | J34: 492.2848 | K34: 465.4978 | L34: 441.44526 | M34: 419.72882
B35: No. of Shares | E35: =Assumptions!O9 -> 1928.4695 | H35: =Scenarios!J68 -> 0.0475 | I35: 556.16673 | J35: 522.30069 | K35: 492.2848 | L35: 465.4978 | M35: 441.44526
H36: =Scenarios!K68 -> 0.05 | I36: 594.67445 | J36: 556.16673 | K36: 522.30069 | L36: 492.2848 | M36: 465.4978
B37: Equity Value per Share | E37: =E34/E35 -> 465.4978
B39: Share Price | E39: =Assumptions!O8 -> 202.71
B40: Discount / Premium | E40: =E39/E37 -> 0.4354693

Sheet Relative Valuation>>

Sheet Comp Valuation
B1: =Cover!B11 -> Adani Power
B2: Peers Valuation
B4: (₹ Crore)
D6: Market Data | J6: Financials | N6: Valuation
B7: Company | C7: Ticker | D7: Share Price | E7: Shares Outstading | F7: Equity Value | G7: Net Debt | H7: Enterprise Value | J7: Revenue | K7: EBITDA | L7: Net Income | N7: EV/Revenue | O7: EV/EBITDA | P7: P/E
B9: Adani Power | D9: =Assumptions!O8 -> 202.71 | E9: =Assumptions!O9 -> 1928.4695 | F9: =E9*D9 -> 390920.05 | G9: ='Historical Data'!Q82+'Historical Data'!Q77+'Historical Data'!Q84-'Historical Data'!Q47 -> 47744.68 | H9: =F9+G9 -> 438664.73 | J9: ='Historical Data'!Q8 -> 54240.52 | K9: ='Historical Data'!Q20 -> 23430.87 | L9: ='Historical Data'!Q30 -> 12971.08 | N9: =H9/J9 -> 8.087399 | O9: =H9/K9 -> 18.721658 | P9: =F9/L9 -> 30.137818
B10: ='Comp Data'!C6 -> NTPC | D10: ='Comp Data'!E6 -> 325.9 | E10: ='Comp Data'!F6 -> 969.67 | F10: =E10*D10 -> 316015.45 | G10: ='Comp Data'!I6 -> 263000.8 | H10: =F10+G10 -> 579016.25 | J10: ='Comp Data'!L6 -> 191058.77 | K10: ='Comp Data'!M6 -> 60059.41 | L10: ='Comp Data'!N6 -> 27762.97 | N10: =H10/J10 -> 3.0305662 | O10: =H10/K10 -> 9.640725 | P10: =F10/L10 -> 11.382624
B11: ='Comp Data'!C7 -> Tata Power Co. | D11: ='Comp Data'!E7 -> 366.05 | E11: ='Comp Data'!F7 -> 319.53 | F11: =E11*D11 -> 116963.96 | G11: ='Comp Data'!I7 -> 62497.27 | H11: =F11+G11 -> 179461.23 | J11: ='Comp Data'!L7 -> 63444.78 | K11: ='Comp Data'!M7 -> 17228.43 | L11: ='Comp Data'!N7 -> 3915.45 | N11: =H11/J11 -> 2.8286208 | O11: =H11/K11 -> 10.416575 | P11: =F11/L11 -> 29.872417
B12: ='Comp Data'!C8 -> JSW Energy | D12: ='Comp Data'!E8 -> 514.2 | E12: ='Comp Data'!F8 -> 183.35 | F12: =E12*D12 -> 94278.57 | G12: ='Comp Data'!I8 -> 71180.56 | H12: =F12+G12 -> 165459.13 | J12: ='Comp Data'!L8 -> 18964.89 | K12: ='Comp Data'!M8 -> 11097.94 | L12: ='Comp Data'!N8 -> 2006.08 | N12: =H12/J12 -> 8.7244972 | O12: =H12/K12 -> 14.908995 | P12: =F12/L12 -> 46.996416
B13: ='Comp Data'!C9 -> Torrent Power | D13: ='Comp Data'!E9 -> 1250 | E13: ='Comp Data'!F9 -> 50.39 | F13: =E13*D13 -> 62987.5 | G13: ='Comp Data'!I9 -> 13139.13 | H13: =F13+G13 -> 76126.63 | J13: ='Comp Data'!L9 -> 29184.09 | K13: ='Comp Data'!M9 -> 5894.85 | L13: ='Comp Data'!N9 -> 2323.84 | N13: =H13/J13 -> 2.6084976 | O13: =H13/K13 -> 12.914091 | P13: =F13/L13 -> 27.104921
B14: ='Comp Data'!C10 -> CESC | D14: ='Comp Data'!E10 -> 141.75 | E14: ='Comp Data'!F10 -> 132.56 | F14: =E14*D14 -> 18790.38 | G14: ='Comp Data'!I10 -> 16098.54 | H14: =F14+G14 -> 34888.92 | J14: ='Comp Data'!L10 -> 18853 | K14: ='Comp Data'!M10 -> 4676 | L14: ='Comp Data'!N10 -> 1554 | N14: =H14/J14 -> 1.8505766 | O14: =H14/K14 -> 7.4612746 | P14: =F14/L14 -> 12.091622
B16: High | N16: =MAX(N10:N14) -> 8.7244972 | O16: =MAX(O10:O14) -> 14.908995 | P16: =MAX(P10:P14) -> 46.996416
B17: 75th Percentile | N17: =QUARTILE(N10:N14,3) -> 3.0305662 | O17: =QUARTILE(O10:O14,3) -> 12.914091 | P17: =QUARTILE(P10:P14,3) -> 29.872417
B18: Average | N18: =AVERAGE(N10:N14) -> 3.8085517 | O18: =AVERAGE(O10:O14) -> 11.068332 | P18: =AVERAGE(P10:P14) -> 25.4896
B19: Median | N19: =QUARTILE(N10:N14,2) -> 2.8286208 | O19: =QUARTILE(O10:O14,2) -> 10.416575 | P19: =QUARTILE(P10:P14,2) -> 27.104921
B20: 25th Percentile | N20: =QUARTILE(N10:N14,1) -> 2.6084976 | O20: =QUARTILE(O10:O14,1) -> 9.640725 | P20: =QUARTILE(P10:P14,1) -> 12.091622
B21: Low | N21: =MIN(N10:N14) -> 1.8505766 | O21: =MIN(O10:O14) -> 7.4612746 | P21: =MIN(P10:P14) -> 11.382624
B24: =B1 -> Adani Power
B25: Comparable Valuation
B27: =B4 -> (₹ Crore)
N28: =N7 -> EV/Revenue | O28: =O7 -> EV/EBITDA | P28: =P7 -> P/E
B29: Implied Enterprise Valuation | N29: =N$19*J9 -> 153425.86 | O29: =O$19*K9 -> 244069.41 | P29: =P31+P30 -> 399324.78
B30: Net Debt | N30: =$G$9 -> 47744.68 | O30: =$G$9 -> 47744.68 | P30: =$G$9 -> 47744.68
B31: Implied Market Value | N31: =N29-N30 -> 105681.18 | O31: =O29-O30 -> 196324.73 | P31: =P19*L9 -> 351580.1
B32: Shares Outstanding | N32: =$E$9 -> 1928.4695 | O32: =$E$9 -> 1928.4695 | P32: =$E$9 -> 1928.4695
B34: Implied Value Per Share | N34: =N31/N32 -> 54.800549 | O34: =O31/O32 -> 101.80339 | P34: =P31/P32 -> 182.31043

Sheet Analysis>>

Sheet Ratio Analysis
B1: =Cover!B11 -> Adani Power
B2: Ratio Analysis
G5: Projected
F6: =G6-1 -> 2026 | G6: =Assumptions!H8 -> 2027 | H6: =G6+1 -> 2028 | I6: =H6+1 -> 2029 | J6: =I6+1 -> 2030 | K6: =J6+1 -> 2031 | L6: =K6+1 -> 2032 | M6: Trend | N6: MEAN | O6: MEDIAN
B8: GROWTH OVER PRIOR PERIOD
C9: Revenue Growth | F9: =Model!J130 -> -0.024601799 | G9: =Model!K130 -> 0.17228946 | H9: =Model!L130 -> 0.21868143 | I9: =Model!M130 -> 0.17285081 | J9: =Model!N130 -> 0.30879657 | K9: =Model!O130 -> 0.31787697 | L9: =Model!P130 -> 0.15649629 | N9: =AVERAGE(F9:L9) -> 0.18891282 | O9: =MEDIAN(F9:L9) -> 0.17285081
C10: Gross Profit Growth | F10: =(Model!J137/Model!I137)-1 -> -0.025815965 | G10: =(Model!K137/Model!J137)-1 -> 0.21765672 | H10: =(Model!L137/Model!K137)-1 -> 0.27958063 | I10: =(Model!M137/Model!L137)-1 -> 0.2084641 | J10: =(Model!N137/Model!M137)-1 -> 0.37577107 | K10: =(Model!O137/Model!N137)-1 -> 0.37023842 | L10: =(Model!P137/Model!O137)-1 -> 0.16836233 | N10: =AVERAGE(F10:L10) -> 0.22775105 | O10: =MEDIAN(F10:L10) -> 0.21765672
C11: EBITDA Growth | F11: =(Model!J147/Model!I147)-1 -> 0.00010674995 | G11: =(Model!K147/Model!J147)-1 -> 0.19762241 | H11: =(Model!L147/Model!K147)-1 -> 0.25684579 | I11: =(Model!M147/Model!L147)-1 -> 0.19436459 | J11: =(Model!N147/Model!M147)-1 -> 0.35496181 | K11: =(Model!O147/Model!N147)-1 -> 0.35456448 | L11: =(Model!P147/Model!O147)-1 -> 0.16184276 | N11: =AVERAGE(F11:L11) -> 0.21718694 | O11: =MEDIAN(F11:L11) -> 0.19762241
C12: EBIT Growth | F12: =(Model!J153/Model!I153)-1 -> -0.012847519 | G12: =(Model!K153/Model!J153)-1 -> 0.2149149 | H12: =(Model!L153/Model!K153)-1 -> 0.27290465 | I12: =(Model!M153/Model!L153)-1 -> 0.20513115 | J12: =(Model!N153/Model!M153)-1 -> 0.37292278 | K12: =(Model!O153/Model!N153)-1 -> 0.36938973 | L12: =(Model!P153/Model!O153)-1 -> 0.16726423 | N12: =AVERAGE(F12:L12) -> 0.22709713 | O12: =MEDIAN(F12:L12) -> 0.2149149
C13: EBT Growth | F13: =(Model!J159/Model!I159)-1 -> -0.017123198 | G13: =(Model!K159/Model!J159)-1 -> 0.26054959 | H13: =(Model!L159/Model!K159)-1 -> 0.27520266 | I13: =(Model!M159/Model!L159)-1 -> 0.19901769 | J13: =(Model!N159/Model!M159)-1 -> 0.40679033 | K13: =(Model!O159/Model!N159)-1 -> 0.38105549 | L13: =(Model!P159/Model!O159)-1 -> 0.18225641 | N13: =AVERAGE(F13:L13) -> 0.24110699 | O13: =MEDIAN(F13:L13) -> 0.26054959
C14: Net Profit Growth | F14: =(Model!J165/Model!I165)-1 -> 0.062852344 | G14: =(Model!K165/Model!J165)-1 -> 0.11930084 | H14: =(Model!L165/Model!K165)-1 -> 0.27520266 | I14: =(Model!M165/Model!L165)-1 -> 0.19901769 | J14: =(Model!N165/Model!M165)-1 -> 0.40679033 | K14: =(Model!O165/Model!N165)-1 -> 0.38105549 | L14: =(Model!P165/Model!O165)-1 -> 0.18225641 | N14: =AVERAGE(F14:L14) -> 0.23235368 | O14: =MEDIAN(F14:L14) -> 0.19901769
C15: EPS Growth | F15: =Model!J173 -> 0.173768 | G15: =Model!K173 -> 0.11930084 | H15: =Model!L173 -> 0.27520266 | I15: =Model!M173 -> 0.19901769 | J15: =Model!N173 -> 0.40679033 | K15: =Model!O173 -> 0.38105549 | L15: =Model!P173 -> 0.18225641 | N15: =AVERAGE(F15:L15) -> 0.24819877 | O15: =MEDIAN(F15:L15) -> 0.19901769
B17: MARGIN ANALYSIS
C18: Gross profit Margin | F18: =Model!J138 -> 0.42113859 | G18: =Model!K138 -> 0.43743653 | H18: =Model!L138 -> 0.45929584 | I18: =Model!M138 -> 0.47324223 | J18: =Model!N138 -> 0.49745926 | K18: =Model!O138 -> 0.51722414 | L18: =Model!P138 -> 0.52253104 | N18: =AVERAGE(F18:L18) -> 0.47547538 | O18: =MEDIAN(F18:L18) -> 0.47324223
C19: SG&A Margin | F19: =(SUM(Model!J141:J143)-Model!J144)/Model!J129 -> -0.016850664 | G19: =(SUM(Model!K141:K143)-Model!K144)/Model!K129 -> -0.010017586 | H19: =(SUM(Model!L141:L143)-Model!L144)/Model!L129 -> -0.0021707968 | I19: =(SUM(Model!M141:M143)-Model!M144)/Model!M129 -> 0.0033108431 | J19: =(SUM(Model!N141:N143)-Model!N144)/Model!N129 -> 0.010951962 | K19: =(SUM(Model!O141:O143)-Model!O144)/Model!O129 -> 0.017173293 | L19: =(SUM(Model!P141:P143)-Model!P144)/Model!P129 -> 0.020168459 | N19: =AVERAGE(F19:L19) -> 0.0032236444 | O19: =MEDIAN(F19:L19) -> 0.0033108431
C20: EBITDA Margin | F20: =Model!J148 -> 0.43798925 | G20: =Model!K148 -> 0.44745412 | H20: =Model!L148 -> 0.46146664 | I20: =Model!M148 -> 0.46993139 | J20: =Model!N148 -> 0.4865073 | K20: =Model!O148 -> 0.50005085 | L20: =Model!P148 -> 0.50236258 | N20: =AVERAGE(F20:L20) -> 0.47225173 | O20: =MEDIAN(F20:L20) -> 0.46993139
C21: EBT Margin | F21: =Model!J154 -> 0.35472589 | G21: =Model!K154 -> 0.36762403 | H21: =Model!L154 -> 0.38398085 | I21: =Model!M154 -> 0.39454915 | J21: =Model!N154 -> 0.4138806 | K21: =Model!O154 -> 0.43005823 | L21: =Model!P154 -> 0.43406243 | N21: =AVERAGE(F21:L21) -> 0.39698303 | O21: =MEDIAN(F21:L21) -> 0.39454915
C22: Net Profit Margin | F22: =Model!J166 -> 0.24718818 | G22: =Model!K166 -> 0.23601503 | H22: =Model!L166 -> 0.24696117 | I22: =Model!M166 -> 0.252471 | J22: =Model!N166 -> 0.2713743 | K22: =Model!O166 -> 0.28438388 | L22: =Model!P166 -> 0.29071833 | N22: =AVERAGE(F22:L22) -> 0.2613017 | O22: =MEDIAN(F22:L22) -> 0.252471
B24: COMMON SIZING
C25: COGS % Sales | F25: =Model!J135 -> 0.57886141 | G25: =Model!K135 -> 0.56256347 | H25: =Model!L135 -> 0.54070416 | I25: =Model!M135 -> 0.52675777 | J25: =Model!N135 -> 0.50254074 | K25: =Model!O135 -> 0.48277586 | L25: =Model!P135 -> 0.47746896 | N25: =AVERAGE(F25:L25) -> 0.52452462 | O25: =MEDIAN(F25:L25) -> 0.52675777
C26: SG&A % Sales | F26: =Model!J145 -> -0.016850664 | G26: =Model!K145 -> -0.010017586 | H26: =Model!L145 -> -0.0021707968 | I26: =Model!M145 -> 0.0033108431 | J26: =Model!N145 -> 0.010951962 | K26: =Model!O145 -> 0.017173293 | L26: =Model!P145 -> 0.020168459 | N26: =AVERAGE(F26:L26) -> 0.0032236444 | O26: =MEDIAN(F26:L26) -> 0.0033108431
C27: Depreciation % Sales | F27: =Model!J151 -> 0.083263358 | G27: =Model!K151 -> 0.079830087 | H27: =Model!L151 -> 0.077485784 | I27: =Model!M151 -> 0.07538224 | J27: =Model!N151 -> 0.072626697 | K27: =Model!O151 -> 0.069992617 | L27: =Model!P151 -> 0.068300147 | N27: =AVERAGE(F27:L27) -> 0.075268704 | O27: =MEDIAN(F27:L27) -> 0.07538224
B29: PROFITABILITY
C30: Return on Asset | F30: =Model!J165/AVERAGE(Model!I237:J237) -> 0.10812959 | G30: =Model!K165/AVERAGE(Model!J237:K237) -> 0.099995193 | H30: =Model!L165/AVERAGE(Model!K237:L237) -> 0.10303905 | I30: =Model!M165/AVERAGE(Model!L237:M237) -> 0.098905921 | J30: =Model!N165/AVERAGE(Model!M237:N237) -> 0.11604617 | K30: =Model!O165/AVERAGE(Model!N237:O237) -> 0.13852512 | L30: =Model!P165/AVERAGE(Model!O237:P237) -> 0.14212842 | N30: =AVERAGE(F30:L30) -> 0.11525278 | O30: =MEDIAN(F30:L30) -> 0.10812959
C31: Return on Capital Employed | F31: =Model!J153/(Model!J255+Model!J240+Model!J245+Model!J246+Model!J247+Model!J248) -> 0.16258304 | G31: =Model!K153/(Model!K255+Model!K240+Model!K245+Model!K246+Model!K247+Model!K248) -> 0.16105152 | H31: =Model!L153/(Model!L255+Model!L240+Model!L245+Model!L246+Model!L247+Model!L248) -> 0.16000711 | I31: =Model!M153/(Model!M255+Model!M240+Model!M245+Model!M246+Model!M247+Model!M248) -> 0.1547625 | J31: =Model!N153/(Model!N255+Model!N240+Model!N245+Model!N246+Model!N247+Model!N248) -> 0.18278396 | K31: =Model!O153/(Model!O255+Model!O240+Model!O245+Model!O246+Model!O247+Model!O248) -> 0.22099915 | L31: =Model!P153/(Model!P255+Model!P240+Model!P245+Model!P246+Model!P247+Model!P248) -> 0.22360648 | N31: =AVERAGE(F31:L31) -> 0.18082768 | O31: =MEDIAN(F31:L31) -> 0.16258304
C32: Return on Invested Capital | F32: =Model!J153*(1-Assumptions!$H$45)/(Model!J235+Model!J251) -> 0.091024748 | G32: =Model!K153*(1-Assumptions!$H$45)/(Model!K235+Model!K251) -> 0.088029704 | H32: =Model!L153*(1-Assumptions!$H$45)/(Model!L235+Model!L251) -> 0.086218652 | I32: =Model!M153*(1-Assumptions!$H$45)/(Model!M235+Model!M251) -> 0.082669914 | J32: =Model!N153*(1-Assumptions!$H$45)/(Model!N235+Model!N251) -> 0.10188157 | K32: =Model!O153*(1-Assumptions!$H$45)/(Model!O235+Model!O251) -> 0.13899603 | L32: =Model!P153*(1-Assumptions!$H$45)/(Model!P235+Model!P251) -> 0.16624719 | N32: =AVERAGE(F32:L32) -> 0.10786683 | O32: =MEDIAN(F32:L32) -> 0.091024748
C33: Return on Equity | F33: =Model!J168/AVERAGE(Model!I255:J255) -> 0.22111196 | G33: =Model!K168/AVERAGE(Model!J255:K255) -> 0.20717996 | H33: =Model!L168/AVERAGE(Model!K255:L255) -> 0.2138051 | I33: =Model!M168/AVERAGE(Model!L255:M255) -> 0.20756224 | J33: =Model!N168/AVERAGE(Model!M255:N255) -> 0.23363847 | K33: =Model!O168/AVERAGE(Model!N255:O255) -> 0.2524484 | L33: =Model!P168/AVERAGE(Model!O255:P255) -> 0.23400204 | N33: =AVERAGE(F33:L33) -> 0.22424974 | O33: =MEDIAN(F33:L33) -> 0.22111196
B35: ASSET TURNOVER
C36: Total Asset Turnover | F36: =Model!J129/AVERAGE(Model!I237:J237) -> 0.43743835 | G36: =Model!K129/AVERAGE(Model!J237:K237) -> 0.42368146 | H36: =Model!L129/AVERAGE(Model!K237:L237) -> 0.41722774 | I36: =Model!M129/AVERAGE(Model!L237:M237) -> 0.39175162 | J36: =Model!N129/AVERAGE(Model!M237:N237) -> 0.42762402 | K36: =Model!O129/AVERAGE(Model!N237:O237) -> 0.48710609 | L36: =Model!P129/AVERAGE(Model!O237:P237) -> 0.48888703 | N36: =AVERAGE(F36:L36) -> 0.43910233 | O36: =MEDIAN(F36:L36) -> 0.42762402
C37: Fixed Asset Turnover | F37: =Model!J129/AVERAGE(Model!I235:J235) -> 0.59352917 | G37: =Model!K129/AVERAGE(Model!J235:K235) -> 0.56046002 | H37: =Model!L129/AVERAGE(Model!K235:L235) -> 0.53787208 | I37: =Model!M129/AVERAGE(Model!L235:M235) -> 0.49553468 | J37: =Model!N129/AVERAGE(Model!M235:N235) -> 0.54295383 | K37: =Model!O129/AVERAGE(Model!N235:O235) -> 0.66117965 | L37: =Model!P129/AVERAGE(Model!O235:P235) -> 0.76437716 | N37: =AVERAGE(F37:L37) -> 0.59370094 | O37: =MEDIAN(F37:L37) -> 0.56046002
C38: Inventory Turnover | F38: =(Model!J135*Model!J129)/AVERAGE(Model!I223:J223) -> 9.1440736 | G38: =(Model!K135*Model!K129)/AVERAGE(Model!J223:K223) -> 9.3296868 | H38: =(Model!L135*Model!L129)/AVERAGE(Model!K223:L223) -> 9.4591483 | I38: =(Model!M135*Model!M129)/AVERAGE(Model!L223:M223) -> 9.3637937 | J38: =(Model!N135*Model!N129)/AVERAGE(Model!M223:N223) -> 9.7631862 | K38: =(Model!O135*Model!O129)/AVERAGE(Model!N223:O223) -> 9.8353974 | L38: =(Model!P135*Model!P129)/AVERAGE(Model!O223:P223) -> 9.4037429 | N38: =AVERAGE(F38:L38) -> 9.4712898 | O38: =MEDIAN(F38:L38) -> 9.4037429
C39: Trade Receivable Turnover | F39: =Model!J129/AVERAGE(Model!I224:J224) -> 4.4185051 | G39: =Model!K129/AVERAGE(Model!J224:K224) -> 5.017667 | H39: =Model!L129/AVERAGE(Model!K224:L224) -> 5.1071653 | I39: =Model!M129/AVERAGE(Model!L224:M224) -> 5.0187728 | J39: =Model!N129/AVERAGE(Model!M224:N224) -> 5.2707346 | K39: =Model!O129/AVERAGE(Model!N224:O224) -> 5.2865112 | L39: =Model!P129/AVERAGE(Model!O224:P224) -> 4.9863206 | N39: =AVERAGE(F39:L39) -> 5.0150966 | O39: =MEDIAN(F39:L39) -> 5.0187728
C40: Trade payable Turnover | F40: =Model!J241/AVERAGE(Model!I129:J129) -> 0.051178362 | G40: =Model!K241/AVERAGE(Model!J129:K129) -> 0.054339772 | H40: =Model!L241/AVERAGE(Model!K129:L129) -> 0.053086678 | I40: =Model!M241/AVERAGE(Model!L129:M129) -> 0.050751228 | J40: =Model!N241/AVERAGE(Model!M129:N129) -> 0.050786855 | K40: =Model!O241/AVERAGE(Model!N129:O129) -> 0.048875067 | L40: =Model!P241/AVERAGE(Model!O129:P129) -> 0.045535976 | N40: =AVERAGE(F40:L40) -> 0.050650562 | O40: =MEDIAN(F40:L40) -> 0.050786855
B42: SOLVENCY RATIO
C43: Debt / Equity | F43: =(Model!J240+Model!J245+Model!J247)/Model!J255 -> 0.84190987 | G43: =(Model!K240+Model!K245+Model!K247)/Model!K255 -> 0.83494734 | H43: =(Model!L240+Model!L245+Model!L247)/Model!L255 -> 0.89685656 | I43: =(Model!M240+Model!M245+Model!M247)/Model!M255 -> 0.91899338 | J43: =(Model!N240+Model!N245+Model!N247)/Model!N255 -> 0.76406241 | K43: =(Model!O240+Model!O245+Model!O247)/Model!O255 -> 0.55011405 | L43: =(Model!P240+Model!P245+Model!P247)/Model!P255 -> 0.41366228 | N43: =AVERAGE(F43:L43) -> 0.74579227 | O43: =MEDIAN(F43:L43) -> 0.83494734
C44: Debt / Capital | F44: =(Model!J240+Model!J245+Model!J247)/(Model!J243+Model!J245+Model!J255) -> 0.45015277 | G44: =(Model!K240+Model!K245+Model!K247)/(Model!K243+Model!K245+Model!K255) -> 0.44812674 | H44: =(Model!L240+Model!L245+Model!L247)/(Model!L243+Model!L245+Model!L255) -> 0.46578022 | I44: =(Model!M240+Model!M245+Model!M247)/(Model!M243+Model!M245+Model!M255) -> 0.47203995 | J44: =(Model!N240+Model!N245+Model!N247)/(Model!N243+Model!N245+Model!N255) -> 0.42604042 | K44: =(Model!O240+Model!O245+Model!O247)/(Model!O243+Model!O245+Model!O255) -> 0.34807425 | L44: =(Model!P240+Model!P245+Model!P247)/(Model!P243+Model!P245+Model!P255) -> 0.28692537 | N44: =AVERAGE(F44:L44) -> 0.4138771 | O44: =MEDIAN(F44:L44) -> 0.44812674
C45: Total Liab / Total Asset | F45: =(Model!J243+Model!J251)/Model!J237 -> 0.51786825 | G45: =(Model!K243+Model!K251)/Model!K237 -> 0.51399039 | H45: =(Model!L243+Model!L251)/Model!L237 -> 0.51902518 | I45: =(Model!M243+Model!M251)/Model!M237 -> 0.51697743 | J45: =(Model!N243+Model!N251)/Model!N237 -> 0.47152306 | K45: =(Model!O243+Model!O251)/Model!O237 -> 0.40003898 | L45: =(Model!P243+Model!P251)/Model!P237 -> 0.34267423 | N45: =AVERAGE(F45:L45) -> 0.46887107 | O45: =MEDIAN(F45:L45) -> 0.51399039
C46: Interest Coverate ratio | F46: =Model!J153/Model!J156 -> 5.7758226 | G46: =Model!K153/Model!K156 -> 7.0384473 | H46: =Model!L153/Model!L156 -> 7.1160218 | I46: =Model!M153/Model!M156 -> 6.9018857 | J46: =Model!N153/Model!N156 -> 8.0779455 | K46: =Model!O153/Model!O156 -> 8.5962718 | L46: =Model!P153/Model!P156 -> 9.5256456 | N46: =AVERAGE(F46:L46) -> 7.5760058 | O46: =MEDIAN(F46:L46) -> 7.1160218
C47: Total Debt / EBITDA | F47: =(Model!J240+Model!J245+Model!J247)/Model!J147 -> 2.2769391 | G47: =(Model!K240+Model!K245+Model!K247)/Model!K147 -> 2.321272 | H47: =(Model!L240+Model!L245+Model!L247)/Model!L147 -> 2.4587733 | I47: =(Model!M240+Model!M245+Model!M247)/Model!M147 -> 2.5980041 | J47: =(Model!N240+Model!N245+Model!N247)/Model!N147 -> 2.01587 | K47: =(Model!O240+Model!O245+Model!O247)/Model!O147 -> 1.3810569 | L47: =(Model!P240+Model!P245+Model!P247)/Model!P147 -> 1.1307088 | N47: =AVERAGE(F47:L47) -> 2.0260892 | O47: =MEDIAN(F47:L47) -> 2.2769391
B49: DAYS
...

Sheet Common Size Analysis
B1: =Cover!B11 -> Adani Power
B2: Income Statement - Common Size
B4: (%)
I5: =Model!K181 -> Projected
F6: =Model!H182 -> 2024 | G6: =Model!I182 -> 2025 | H6: =Model!J182 -> 2026 | I6: =Model!K182 -> 2027 | J6: =Model!L182 -> 2028 | K6: =Model!M182 -> 2029 | L6: =Model!N182 -> 2030 | M6: =Model!O182 -> 2031 | N6: =Model!P182 -> 2032
B7: REVENUE
C8: Sales | F8: =Model!H129/Model!H$129 -> 1 | G8: =Model!I129/Model!I$129 -> 1 | H8: =Model!J129/Model!J$129 -> 1 | I8: =Model!K129/Model!K$129 -> 1 | J8: =Model!L129/Model!L$129 -> 1 | K8: =Model!M129/Model!M$129 -> 1 | L8: =Model!N129/Model!N$129 -> 1 | M8: =Model!O129/Model!O$129 -> 1 | N8: =Model!P129/Model!P$129 -> 1
B9: COGS
