Workbook
Name IQ_CH: 110000
Name IQ_CQ: 5000
Name IQ_CY: 10000
Name IQ_DAILY: 500000
Name IQ_FH: 100000
Name IQ_FQ: 500
Name IQ_FY: 1000
Name IQ_LTM: 2000
Name IQ_MONTH: 15000
Name IQ_NTM: 6000
Name IQ_WEEK: 50000
Name IQ_YTD: 3000
Name UPDATE: 'Data Sheet'!$E$1
Name UPDATE: #REF!

Sheet Financials>

Sheet Historical FS
B2: ="Historical Financial Statement - "&'Data Sheet'!B1 -> Historical Financial Statement - DYNACONS SYSTEMS & SOLUTIONS LTD
B3: Years | C3: 42460 | D3: 42825 | E3: 43190 | F3: 43555 | G3: 43921 | H3: 44286 | I3: 44651 | J3: 45016 | K3: 45382 | L3: 45747
A5: # | B5: Income Statement
B6: Sales | C6: =IFERROR('Data Sheet'!B17,0) -> 124.18 | D6: =IFERROR('Data Sheet'!C17,0) -> 158.29 | E6: =IFERROR('Data Sheet'!D17,0) -> 210.7 | F6: =IFERROR('Data Sheet'!E17,0) -> 303.72 | G6: =IFERROR('Data Sheet'!F17,0) -> 327.95 | H6: =IFERROR('Data Sheet'!G17,0) -> 435.94 | I6: =IFERROR('Data Sheet'!H17,0) -> 653.98 | J6: =IFERROR('Data Sheet'!I17,0) -> 804.15 | ... L6: =IFERROR('Data Sheet'!K17,0) -> 1266.83
B7: Sales Growth | C7: - | D7: =D6/C6-1 -> 0.27468191 | E7: =E6/D6-1 -> 0.33110114 | F7: =F6/E6-1 -> 0.44148078 | G7: =G6/F6-1 -> 0.079777427 | H7: =H6/G6-1 -> 0.329288 | I7: =I6/H6-1 -> 0.50016057 | J7: =J6/I6-1 -> 0.22962476 | K7: =K6/J6-1 -> 0.27392899 | L7: =L6/K6-1 -> 0.23661939
B9: COGS | C9: =IFERROR(SUM('Data Sheet'!B18,'Data Sheet'!B20:B22)-1*'Data Sheet'!B19,0) -> 117.66 | D9: =IFERROR(SUM('Data Sheet'!C18,'Data Sheet'!C20:C22)-1*'Data Sheet'!C19,0) -> 150.15 | E9: =IFERROR(SUM('Data Sheet'!D18,'Data Sheet'!D20:D22)-1*'Data Sheet'!D19,0) -> 198.95 | F9: =IFERROR(SUM('Data Sheet'!E18,'Data Sheet'!E20:E22)-1*'Data Sheet'!E19,0) -> 285.81 | G9: =IFERROR(SUM('Data Sheet'!F18,'Data Sheet'!F20:F22)-1*'Data Sheet'!F19,0) -> 306.23 | H9: =IFERROR(SUM('Data Sheet'!G18,'Data Sheet'!G20:G22)-1*'Data Sheet'!G19,0) -> 412.32 | I9: =IFERROR(SUM('Data Sheet'!H18,'Data Sheet'!H20:H22)-1*'Data Sheet'!H19,0) -> 616.1 | J9: =IFERROR(SUM('Data Sheet'!I18,'Data Sheet'!I20:I22)-1*'Data Sheet'!I19,0) -> 737.93 | ... L9: =IFERROR(SUM('Data Sheet'!K18,'Data Sheet'!K20:K22)-1*'Data Sheet'!K19,0) -> 1149.21
B10: COGS % Sales | C10: =C9/C6 -> 0.94749557 | D10: =D9/D6 -> 0.9485754 | E10: =E9/E6 -> 0.94423351 | F10: =F9/F6 -> 0.94103121 | G10: =G9/G6 -> 0.93377039 | H10: =H9/H6 -> 0.94581823 | I10: =I9/I6 -> 0.94207774 | J10: =J9/J6 -> 0.91765218 | ... L10: =L9/L6 -> 0.90715408
B12: Gross Profit | C12: =C6-C9 -> 6.52 | D12: =D6-D9 -> 8.14 | E12: =E6-E9 -> 11.75 | F12: =F6-F9 -> 17.91 | G12: =G6-G9 -> 21.72 | H12: =H6-H9 -> 23.62 | I12: =I6-I9 -> 37.88 | J12: =J6-J9 -> 66.22 | ... L12: =L6-L9 -> 117.62
B13: Gross Margins | C13: =C12/C6 -> 0.052504429 | D13: =D12/D6 -> 0.0514246 | E13: =E12/E6 -> 0.055766493 | F13: =F12/F6 -> 0.058968787 | G13: =G12/G6 -> 0.066229608 | H13: =H12/H6 -> 0.054181768 | I13: =I12/I6 -> 0.057922261 | J13: =J12/J6 -> 0.082347821 | ... L13: =L12/L6 -> 0.092845922
B15: Selling & General Expenses | C15: =IFERROR(SUM('Data Sheet'!B23:B24),0) -> 2.35 | D15: =IFERROR(SUM('Data Sheet'!C23:C24),0) -> 3.4 | E15: =IFERROR(SUM('Data Sheet'!D23:D24),0) -> 5.08 | F15: =IFERROR(SUM('Data Sheet'!E23:E24),0) -> 6.03 | G15: =IFERROR(SUM('Data Sheet'!F23:F24),0) -> 7.11 | H15: =IFERROR(SUM('Data Sheet'!G23:G24),0) -> 4.95 | I15: =IFERROR(SUM('Data Sheet'!H23:H24),0) -> 7.23 | J15: =IFERROR(SUM('Data Sheet'!I23:I24),0) -> 11.63 | ... L15: =IFERROR(SUM('Data Sheet'!K23:K24),0) -> 12.4
B16: S&G Exp % Sales | C16: =C15/C6 -> 0.018924142 | D16: =D15/D6 -> 0.021479563 | E16: =E15/E6 -> 0.024110109 | F16: =F15/F6 -> 0.019853813 | G16: =G15/G6 -> 0.021680134 | H16: =H15/H6 -> 0.011354774 | I16: =I15/I6 -> 0.011055384 | J16: =J15/J6 -> 0.014462476 | ... L16: =L15/L6 -> 0.0097882115
B18: EBITDA | C18: =C12-C15 -> 4.17 | D18: =D12-D15 -> 4.74 | E18: =E12-E15 -> 6.67 | F18: =F12-F15 -> 11.88 | G18: =G12-G15 -> 14.61 | H18: =H12-H15 -> 18.67 | I18: =I12-I15 -> 30.65 | J18: =J12-J15 -> 54.59 | ... L18: =L12-L15 -> 105.22
B19: EBITDA Margins | C19: =C18/C6 -> 0.033580287 | D19: =D18/D6 -> 0.029945038 | E19: =E18/E6 -> 0.031656383 | F19: =F18/F6 -> 0.039114974 | G19: =G18/G6 -> 0.044549474 | H19: =H18/H6 -> 0.042826995 | I19: =I18/I6 -> 0.046866877 | J19: =J18/J6 -> 0.067885345 | ... L19: =L18/L6 -> 0.083057711
B21: Interest | C21: =IFERROR('Data Sheet'!B27,0) -> 2.75 | D21: =IFERROR('Data Sheet'!C27,0) -> 2.91 | E21: =IFERROR('Data Sheet'!D27,0) -> 3.9 | F21: =IFERROR('Data Sheet'!E27,0) -> 6.03 | G21: =IFERROR('Data Sheet'!F27,0) -> 7.76 | H21: =IFERROR('Data Sheet'!G27,0) -> 7.17 | I21: =IFERROR('Data Sheet'!H27,0) -> 9.02 | J21: =IFERROR('Data Sheet'!I27,0) -> 10.91 | ... L21: =IFERROR('Data Sheet'!K27,0) -> 13.27
B22: Interest % Sales | C22: =C21/C6 -> 0.022145273 | D22: =D21/D6 -> 0.018383979 | E22: =E21/E6 -> 0.018509729 | F22: =F21/F6 -> 0.019853813 | G22: =G21/G6 -> 0.023662144 | H22: =H21/H6 -> 0.016447218 | I22: =I21/I6 -> 0.013792471 | J22: =J21/J6 -> 0.013567121 | ... L22: =L21/L6 -> 0.010474965
B24: Depreciation | C24: =IFERROR('Data Sheet'!B26,0) -> 0.62 | D24: =IFERROR('Data Sheet'!C26,0) -> 0.61 | E24: =IFERROR('Data Sheet'!D26,0) -> 0.76 | F24: =IFERROR('Data Sheet'!E26,0) -> 0.72 | G24: =IFERROR('Data Sheet'!F26,0) -> 1.03 | H24: =IFERROR('Data Sheet'!G26,0) -> 1.26 | I24: =IFERROR('Data Sheet'!H26,0) -> 1.36 | J24: =IFERROR('Data Sheet'!I26,0) -> 1.36 | ... L24: =IFERROR('Data Sheet'!K26,0) -> 1.65
B25: Depreciation%Sales | C25: =C24/C6 -> 0.0049927525 | D25: =D24/D6 -> 0.0038536863 | E25: =E24/E6 -> 0.0036070242 | F25: =F24/F6 -> 0.0023706045 | G25: =G24/G6 -> 0.0031407227 | H25: =H24/H6 -> 0.002890306 | I25: =I24/I6 -> 0.0020795743 | J25: =J24/J6 -> 0.0016912268 | ... L25: =L24/L6 -> 0.0013024636
B27: Earnings Before Tax | C27: =IFERROR(C18-SUM(C24,C21),0) -> 0.8 | D27: =IFERROR(D18-SUM(D24,D21),0) -> 1.22 | E27: =IFERROR(E18-SUM(E24,E21),0) -> 2.01 | F27: =IFERROR(F18-SUM(F24,F21),0) -> 5.13 | G27: =IFERROR(G18-SUM(G24,G21),0) -> 5.82 | H27: =IFERROR(H18-SUM(H24,H21),0) -> 10.24 | I27: =IFERROR(I18-SUM(I24,I21),0) -> 20.27 | J27: =IFERROR(J18-SUM(J24,J21),0) -> 42.32 | ... L27: =IFERROR(L18-SUM(L24,L21),0) -> 90.3
B28: EBT % Sales | C28: =C27/C6 -> 0.0064422612 | D28: =D27/D6 -> 0.0077073725 | E28: =E27/E6 -> 0.0095396298 | F28: =F27/F6 -> 0.016890557 | G28: =G27/G6 -> 0.017746608 | H28: =H27/H6 -> 0.023489471 | I28: =I27/I6 -> 0.030994832 | J28: =J27/J6 -> 0.052626997 | ... L28: =L27/L6 -> 0.071280282
B30: Tax | C30: =IFERROR('Data Sheet'!B29,0) -> 0.4 | D30: =IFERROR('Data Sheet'!C29,0) -> 0.41 | E30: =IFERROR('Data Sheet'!D29,0) -> 0.94 | F30: =IFERROR('Data Sheet'!E29,0) -> 2.13 | G30: =IFERROR('Data Sheet'!F29,0) -> 1.94 | H30: =IFERROR('Data Sheet'!G29,0) -> 2.88 | I30: =IFERROR('Data Sheet'!H29,0) -> 5.6 | J30: =IFERROR('Data Sheet'!I29,0) -> 11.23 | ... L30: =IFERROR('Data Sheet'!K29,0) -> 24.6
B31: Effective Tax Rate | C31: =C30/C27 -> 0.5 | D31: =D30/D27 -> 0.33606557 | E31: =E30/E27 -> 0.46766169 | F31: =F30/F27 -> 0.41520468 | G31: =G30/G27 -> 0.33333333 | H31: =H30/H27 -> 0.28125 | I31: =I30/I27 -> 0.27627035 | J31: =J30/J27 -> 0.26535917 | ... L31: =L30/L27 -> 0.27242525
B33: Net Profit | C33: =IFERROR(C27-C30,0) -> 0.4 | D33: =IFERROR(D27-D30,0) -> 0.81 | E33: =IFERROR(E27-E30,0) -> 1.07 | F33: =IFERROR(F27-F30,0) -> 3 | G33: =IFERROR(G27-G30,0) -> 3.88 | H33: =IFERROR(H27-H30,0) -> 7.36 | I33: =IFERROR(I27-I30,0) -> 14.67 | J33: =IFERROR(J27-J30,0) -> 31.09 | ... L33: =IFERROR(L27-L30,0) -> 65.7
B34: Net Margins | C34: =C33/C6 -> 0.0032211306 | D34: =D33/D6 -> 0.00511719 | E34: =E33/E6 -> 0.0050783104 | F34: =F33/F6 -> 0.0098775188 | G34: =G33/G6 -> 0.011831072 | H34: =H33/H6 -> 0.016883057 | I34: =I33/I6 -> 0.022431879 | J34: =J33/J6 -> 0.038661941 | ... L34: =L33/L6 -> 0.051861734
B36: No of Equity Shares | C36: =IFERROR('Data Sheet'!B69,0) -> 5923080 | D36: =IFERROR('Data Sheet'!C69,0) -> 6378080 | E36: =IFERROR('Data Sheet'!D69,0) -> 6908080 | F36: =IFERROR('Data Sheet'!E69,0) -> 9173080 | G36: =IFERROR('Data Sheet'!F69,0) -> 9173080 | H36: =IFERROR('Data Sheet'!G69,0) -> 10133080 | I36: =IFERROR('Data Sheet'!H69,0) -> 11278080 | J36: =IFERROR('Data Sheet'!I69,0) -> 12693080 | ... L36: =IFERROR('Data Sheet'!K69,0) -> 12725330
B38: Earnings per Share | C38: =IFERROR(C33/C36,0) -> 6.7532432e-08 | D38: =IFERROR(D33/D36,0) -> 1.2699747e-07 | E38: =IFERROR(E33/E36,0) -> 1.5489108e-07 | F38: =IFERROR(F33/F36,0) -> 3.2704392e-07 | G38: =IFERROR(G33/G36,0) -> 4.229768e-07 | H38: =IFERROR(H33/H36,0) -> 7.2633395e-07 | I38: =IFERROR(I33/I36,0) -> 1.3007533e-06 | J38: =IFERROR(J33/J36,0) -> 2.4493661e-06 | ... L38: =IFERROR(L33/L36,0) -> 5.1629309e-06
B39: EPS Growth % | D39: =IFERROR(D38/C38-1,0) -> 0.88054038 | E39: =IFERROR(E38/D38-1,0) -> 0.21963917 | F39: =IFERROR(F38/E38-1,0) -> 1.1114444 | G39: =IFERROR(G38/F38-1,0) -> 0.29333333 | H39: =IFERROR(H38/G38-1,0) -> 0.71719572 | I39: =IFERROR(I38/H38-1,0) -> 0.79084748 | J39: =IFERROR(J38/I38-1,0) -> 0.8830366 | K39: =IFERROR(K38/J38-1,0) -> 0.59220994 | L39: =IFERROR(L38/K38-1,0) -> 0.32386067
B41: Dividend per Share | C41: =IFERROR(#REF!/'Historical FS'!C36,0) -> 0 | D41: =IFERROR(#REF!/'Historical FS'!D36,0) -> 0 | E41: =IFERROR(#REF!/'Historical FS'!E36,0) -> 0 | F41: =IFERROR(#REF!/'Historical FS'!F36,0) -> 0 | G41: =IFERROR(#REF!/'Historical FS'!G36,0) -> 0 | H41: =IFERROR(#REF!/'Historical FS'!H36,0) -> 0 | I41: =IFERROR(#REF!/'Historical FS'!I36,0) -> 0 | J41: =IFERROR(#REF!/'Historical FS'!J36,0) -> 0 | ... L41: =IFERROR(#REF!/'Historical FS'!L36,0) -> 0
B42: Dividend payout ratio | C42: =IFERROR(C41/C38,0) -> 0 | D42: =IFERROR(D41/D38,0) -> 0 | E42: =IFERROR(E41/E38,0) -> 0 | F42: =IFERROR(F41/F38,0) -> 0 | G42: =IFERROR(G41/G38,0) -> 0 | H42: =IFERROR(H41/H38,0) -> 0 | I42: =IFERROR(I41/I38,0) -> 0 | J42: =IFERROR(J41/J38,0) -> 0 | ... L42: =IFERROR(L41/L38,0) -> 0
B44: Retained Earnings | C44: =IFERROR(IF(C38>C41,1-C42,0),0) -> 1 | D44: =IFERROR(IF(D38>D41,1-D42,0),0) -> 1 | E44: =IFERROR(IF(E38>E41,1-E42,0),0) -> 1 | F44: =IFERROR(IF(F38>F41,1-F42,0),0) -> 1 | G44: =IFERROR(IF(G38>G41,1-G42,0),0) -> 1 | H44: =IFERROR(IF(H38>H41,1-H42,0),0) -> 1 | I44: =IFERROR(IF(I38>I41,1-I42,0),0) -> 1 | J44: =IFERROR(IF(J38>J41,1-J42,0),0) -> 1 | ... L44: =IFERROR(IF(L38>L41,1-L42,0),0) -> 1
A46: # | B46: Balance Sheet
B47: Equity Share Capital | C47: =IFERROR('Data Sheet'!B56,0) -> 5.92 | D47: =IFERROR('Data Sheet'!C56,0) -> 6.38 | E47: =IFERROR('Data Sheet'!D56,0) -> 6.91 | F47: =IFERROR('Data Sheet'!E56,0) -> 9.17 | G47: =IFERROR('Data Sheet'!F56,0) -> 9.17 | H47: =IFERROR('Data Sheet'!G56,0) -> 10.13 | I47: =IFERROR('Data Sheet'!H56,0) -> 11.28 | J47: =IFERROR('Data Sheet'!I56,0) -> 12.69 | ... L47: =IFERROR('Data Sheet'!K56,0) -> 12.73
B48: Reserves | C48: =IFERROR('Data Sheet'!B57,0) -> 10.95 | D48: =IFERROR(#REF!,0) -> 0 | E48: =IFERROR(#REF!,0) -> 0 | F48: =IFERROR(#REF!,0) -> 0 | G48: =IFERROR(#REF!,0) -> 0 | H48: =IFERROR(#REF!,0) -> 0 | I48: =IFERROR(#REF!,0) -> 0 | J48: =IFERROR(#REF!,0) -> 0 | K48: =IFERROR(#REF!,0) -> 0 | L48: =IFERROR(#REF!,0) -> 0
B49: Borrowings | C49: =IFERROR('Data Sheet'!B58,0) -> 20.87 | D49: =IFERROR(#REF!,0) -> 0 | E49: =IFERROR(#REF!,0) -> 0 | F49: =IFERROR(#REF!,0) -> 0 | G49: =IFERROR(#REF!,0) -> 0 | H49: =IFERROR(#REF!,0) -> 0 | I49: =IFERROR(#REF!,0) -> 0 | J49: =IFERROR(#REF!,0) -> 0 | K49: =IFERROR(#REF!,0) -> 0 | L49: =IFERROR(#REF!,0) -> 0
B50: Other Liabilities | C50: =IFERROR('Data Sheet'!B59,0) -> 11.95 | D50: =IFERROR(#REF!,0) -> 0 | E50: =IFERROR(#REF!,0) -> 0 | F50: =IFERROR(#REF!,0) -> 0 | G50: =IFERROR(#REF!,0) -> 0 | H50: =IFERROR(#REF!,0) -> 0 | I50: =IFERROR(#REF!,0) -> 0 | J50: =IFERROR(#REF!,0) -> 0 | K50: =IFERROR(#REF!,0) -> 0 | L50: =IFERROR(#REF!,0) -> 0
B51: Total Liabilities | C51: =IFERROR('Data Sheet'!B60,0) -> 49.69 | D51: =IFERROR('Data Sheet'!C60,0) -> 52.99 | E51: =IFERROR('Data Sheet'!D60,0) -> 69.43 | F51: =IFERROR('Data Sheet'!E60,0) -> 98.02 | G51: =IFERROR('Data Sheet'!F60,0) -> 122.14 | H51: =IFERROR('Data Sheet'!G60,0) -> 180.56 | I51: =IFERROR('Data Sheet'!H60,0) -> 298.92 | J51: =IFERROR('Data Sheet'!I60,0) -> 402.21 | ... L51: =IFERROR('Data Sheet'!K60,0) -> 774.07
B53: Fixed Assets Net Block | C53: =IFERROR('Data Sheet'!B61,0) -> 3.46 | D53: =IFERROR('Data Sheet'!C61,0) -> 3.03 | E53: =IFERROR('Data Sheet'!D61,0) -> 2.85 | F53: =IFERROR('Data Sheet'!E61,0) -> 2.5 | G53: =IFERROR('Data Sheet'!F61,0) -> 3.74 | H53: =IFERROR('Data Sheet'!G61,0) -> 6.39 | I53: =IFERROR('Data Sheet'!H61,0) -> 6.09 | J53: =IFERROR('Data Sheet'!I61,0) -> 6.73 | ... L53: =IFERROR('Data Sheet'!K61,0) -> 9.21
B54: Capital Work in Progress | C54: =IFERROR('Data Sheet'!B62,0) -> 0 | D54: =IFERROR('Data Sheet'!C62,0) -> 0 | E54: =IFERROR('Data Sheet'!D62,0) -> 0 | F54: =IFERROR('Data Sheet'!E62,0) -> 0 | G54: =IFERROR('Data Sheet'!F62,0) -> 0 | H54: =IFERROR('Data Sheet'!G62,0) -> 0 | I54: =IFERROR('Data Sheet'!H62,0) -> 0 | J54: =IFERROR('Data Sheet'!I62,0) -> 0 | ... L54: =IFERROR('Data Sheet'!K62,0) -> 21.95
B55: Investments | C55: =IFERROR('Data Sheet'!B63,0) -> 0.01 | D55: =IFERROR('Data Sheet'!C63,0) -> 0.06 | E55: =IFERROR('Data Sheet'!D63,0) -> 0.06 | F55: =IFERROR('Data Sheet'!E63,0) -> 0.06 | G55: =IFERROR('Data Sheet'!F63,0) -> 0.06 | H55: =IFERROR('Data Sheet'!G63,0) -> 0.44 | I55: =IFERROR('Data Sheet'!H63,0) -> 0.56 | J55: =IFERROR('Data Sheet'!I63,0) -> 0.55 | ... L55: =IFERROR('Data Sheet'!K63,0) -> 0.9
B56: Other Assets | C56: =IFERROR('Data Sheet'!B64-SUM('Data Sheet'!B66:B68),0) -> 3 | D56: =IFERROR('Data Sheet'!C64-SUM('Data Sheet'!C66:C68),0) -> 2.98 | E56: =IFERROR('Data Sheet'!D64-SUM('Data Sheet'!D66:D68),0) -> 4.32 | F56: =IFERROR('Data Sheet'!E64-SUM('Data Sheet'!E66:E68),0) -> 3.36 | G56: =IFERROR('Data Sheet'!F64-SUM('Data Sheet'!F66:F68),0) -> 9.01 | H56: =IFERROR('Data Sheet'!G64-SUM('Data Sheet'!G66:G68),0) -> 6.65 | I56: =IFERROR('Data Sheet'!H64-SUM('Data Sheet'!H66:H68),0) -> 10.36 | J56: =IFERROR('Data Sheet'!I64-SUM('Data Sheet'!I66:I68),0) -> 11.9 | ... L56: =IFERROR('Data Sheet'!K64-SUM('Data Sheet'!K66:K68),0) -> 142.88
B57: Total Non Current Assets | C57: =SUM(C53:C56) -> 6.47 | D57: =SUM(D53:D56) -> 6.07 | E57: =SUM(E53:E56) -> 7.23 | F57: =SUM(F53:F56) -> 5.92 | G57: =SUM(G53:G56) -> 12.81 | H57: =SUM(H53:H56) -> 13.48 | I57: =SUM(I53:I56) -> 17.01 | J57: =SUM(J53:J56) -> 19.18 | ... L57: =SUM(L53:L56) -> 174.94
...

Sheet Forecasting
B3: ='Data Sheet'!$B$1&" - "&'Data Sheet'!A17&" Forecasting" -> DYNACONS SYSTEMS & SOLUTIONS LTD - Sales Forecasting | G3: ='Data Sheet'!$B$1&" - "&'Data Sheet'!A32&" Forecasting" -> DYNACONS SYSTEMS & SOLUTIONS LTD - EBITDA Forecasting
B4: Year Weight | C4: Year | D4: Sales | E4: Sales Growth | G4: Year Weight | H4: Year | I4: EBITDA | J4: EBITDA Growth
B5: 1 | C5: ='Data Sheet'!B16 -> 42460 | D5: {=TRANSPOSE('Data Sheet'!B17:K17)} -> 124.18 | G5: 1 | H5: ='Data Sheet'!B16 -> 42460 | I5: {=TRANSPOSE('Data Sheet'!B32:'Data Sheet'!B32:K32)} -> 4.68
B6: =B5+1 -> 2 | C6: =C5+365 -> 42825 | D6: 158.29 | E6: =D6/D5-1 -> 0.27468191 | G6: =G5+1 -> 2 | H6: =H5+365 -> 42825 | I6: 5.17 | J6: =I6/I5-1 -> 0.10470085
B7: =B6+1 -> 3 | C7: =C6+365 -> 43190 | D7: 210.7 | E7: =D7/D6-1 -> 0.33110114 | G7: =G6+1 -> 3 | H7: =H6+365 -> 43190 | I7: 7.49 | J7: =I7/I6-1 -> 0.44874275
B8: =B7+1 -> 4 | C8: =C7+365 -> 43555 | D8: 303.72 | E8: =D8/D7-1 -> 0.44148078 | G8: =G7+1 -> 4 | H8: =H7+365 -> 43555 | I8: 13.07 | J8: =I8/I7-1 -> 0.74499332
B9: =B8+1 -> 5 | C9: =C8+365 -> 43920 | D9: 327.95 | E9: =D9/D8-1 -> 0.079777427 | G9: =G8+1 -> 5 | H9: =H8+365 -> 43920 | I9: 16.85 | J9: =I9/I8-1 -> 0.28921194
B10: =B9+1 -> 6 | C10: =C9+365 -> 44285 | D10: 435.94 | E10: =D10/D9-1 -> 0.329288 | G10: =G9+1 -> 6 | H10: =H9+365 -> 44285 | I10: 20.53 | J10: =I10/I9-1 -> 0.21839763
B11: =B10+1 -> 7 | C11: =C10+365 -> 44650 | D11: 653.98 | E11: =D11/D10-1 -> 0.50016057 | G11: =G10+1 -> 7 | H11: =H10+365 -> 44650 | I11: 32.44 | J11: =I11/I10-1 -> 0.58012664
B12: =B11+1 -> 8 | C12: =C11+365 -> 45015 | D12: 804.15 | E12: =D12/D11-1 -> 0.22962476 | G12: =G11+1 -> 8 | H12: =H11+365 -> 45015 | I12: 56.88 | J12: =I12/I11-1 -> 0.75339088
B13: =B12+1 -> 9 | C13: =C12+365 -> 45380 | D13: 1024.43 | E13: =D13/D12-1 -> 0.27392899 | G13: =G12+1 -> 9 | H13: =H12+365 -> 45380 | I13: 82.6 | J13: =I13/I12-1 -> 0.45218003
B14: =B13+1 -> 10 | C14: =C13+365 -> 45745 | D14: 1266.83 | E14: =D14/D13-1 -> 0.23661939 | G14: =G13+1 -> 10 | H14: =H13+365 -> 45745 | I14: 111.93 | J14: =I14/I13-1 -> 0.35508475
B15: =B14+1 -> 11 | C15: =C14+365 -> 46110 | D15: =FORECAST(B15,_xlfn.ANCHORARRAY($D$5),$B$5:$B$14) -> 1213.4453 | E15: =D15/D14-1 -> -0.042140356 | G15: =G14+1 -> 11 | H15: =H14+365 -> 46110 | I15: =FORECAST(G15,_xlfn.ANCHORARRAY($I$5),$G$5:$G$14) -> 95.697333 | J15: =I15/I14-1 -> -0.14502516
B16: =B15+1 -> 12 | C16: =C15+365 -> 46475 | D16: =FORECAST(B16,_xlfn.ANCHORARRAY($D$5),$B$5:$B$14) -> 1337.5232 | E16: =D16/D15-1 -> 0.10225255 | G16: =G15+1 -> 12 | H16: =H15+365 -> 46475 | I16: =FORECAST(G16,_xlfn.ANCHORARRAY($I$5),$G$5:$G$14) -> 106.70339 | J16: =I16/I15-1 -> 0.11500906
B17: =B16+1 -> 13 | C17: =C16+365 -> 46840 | D17: =FORECAST(B17,_xlfn.ANCHORARRAY($D$5),$B$5:$B$14) -> 1461.6011 | E17: =D17/D16-1 -> 0.092766898 | G17: =G16+1 -> 13 | H17: =H16+365 -> 46840 | I17: =FORECAST(G17,_xlfn.ANCHORARRAY($I$5),$G$5:$G$14) -> 117.70945 | J17: =I17/I16-1 -> 0.1031463
B18: =B17+1 -> 14 | C18: =C17+365 -> 47205 | D18: =FORECAST(B18,_xlfn.ANCHORARRAY($D$5),$B$5:$B$14) -> 1585.679 | E18: =D18/D17-1 -> 0.084891753 | G18: =G17+1 -> 14 | H18: =H17+365 -> 47205 | I18: =FORECAST(G18,_xlfn.ANCHORARRAY($I$5),$G$5:$G$14) -> 128.71552 | J18: =I18/I17-1 -> 0.093501925
B19: =B18+1 -> 15 | C19: =C18+365 -> 47570 | D19: =FORECAST(B19,_xlfn.ANCHORARRAY($D$5),$B$5:$B$14) -> 1709.7568 | E19: =D19/D18-1 -> 0.078249054 | G19: =G18+1 -> 15 | H19: =H18+365 -> 47570 | I19: =FORECAST(G19,_xlfn.ANCHORARRAY($I$5),$G$5:$G$14) -> 139.72158 | J19: =I19/I18-1 -> 0.085506868

Sheet Data>

Sheet Data Sheet
A1: COMPANY NAME | B1: DYNACONS SYSTEMS & SOLUTIONS LTD | E1: =IF(B2<>B3, "A NEW VERSION OF THE WORKSHEET IS AVAILABLE", "")
A2: LATEST VERSION | B2: 2.1 | E2: PLEASE DO NOT MAKE ANY CHANGES TO THIS SHEET
A3: CURRENT VERSION | B3: 2.1
A5: META
A6: Number of shares | B6: =IF(B9>0, B9/B8, 0) -> 1.2725305
A7: Face Value | B7: 10
A8: Current Price | B8: 956.15
A9: Market Capitalization | B9: 1216.73
A15: PROFIT & LOSS
A16: Report Date | B16: 42460 | C16: 42825 | D16: 43190 | E16: 43555 | F16: 43921 | G16: 44286 | H16: 44651 | I16: 45016 | J16: 45382 | K16: 45747
A17: Sales | B17: 124.18 | C17: 158.29 | D17: 210.7 | E17: 303.72 | F17: 327.95 | G17: 435.94 | H17: 653.98 | I17: 804.15 | J17: 1024.43 | K17: 1266.83
A18: Raw Material Cost | B18: 109.24 | C18: 141.47 | D18: 182.83 | E18: 264.14 | F18: 275.58 | G18: 421.85 | H18: 616.82 | I18: 672.67 | J18: 932.54 | K18: 1090.26
A19: Change in Inventory | B19: -0.82 | C19: 2.57 | D19: 4.61 | E19: 2.98 | F19: -8.07 | G19: 33.75 | H19: 28.44 | I19: -34.27 | J19: 36.75 | K19: -15.15
A20: Power and Fuel | B20: 0.11 | C20: 0.11 | D20: 0.11 | E20: 0.1 | F20: 0.11 | G20: 0.06 | H20: 0.08 | I20: 0.1 | J20: 0.13 | K20: 0.15
A21: Other Mfr. Exp | B21: 0.08 | C21: 0.09 | D21: 0.15 | E21: 0.07 | F21: 0.09 | G21: 0.22 | H21: 0.07 | I21: 0.13 | J21: 0.07 | K21: 0.08
A22: Employee Cost | B22: 7.41 | C22: 11.05 | D22: 20.47 | E22: 24.48 | F22: 22.38 | G22: 23.94 | H22: 27.57 | I22: 30.76 | J22: 38.55 | K22: 43.57
A23: Selling and admin | B23: 2.22 | C23: 2.98 | D23: 4.46 | E23: 5.76 | F23: 6.81 | G23: 4.11 | H23: 6.36 | I23: 10.73 | J23: 10.43 | K23: 10.69
A24: Other Expenses | B24: 0.13 | C24: 0.42 | D24: 0.62 | E24: 0.27 | F24: 0.3 | G24: 0.84 | H24: 0.87 | I24: 0.9 | J24: 1.24 | K24: 1.71
A25: Other Income | B25: 0.52 | C25: 0.42 | D25: 0.83 | E25: 1.18 | F25: 2.23 | G25: 1.85 | H25: 1.78 | I25: 2.29 | J25: 4.38 | K25: 6.71
A26: Depreciation | B26: 0.62 | C26: 0.61 | D26: 0.76 | E26: 0.72 | F26: 1.03 | G26: 1.26 | H26: 1.36 | I26: 1.36 | J26: 1.52 | K26: 1.65
A27: Interest | B27: 2.75 | C27: 2.91 | D27: 3.9 | E27: 6.03 | F27: 7.76 | G27: 7.17 | H27: 9.02 | I27: 10.91 | J27: 8.87 | K27: 13.27
... A30: Net profit | B30: 0.91 | C30: 1.24 | D30: 1.89 | E30: 4.19 | F30: 6.12 | G30: 9.22 | H30: 16.46 | I30: 33.38 | J30: 53.96 | K30: 72.41
A31: Dividend Amount | F31: 0.46 | G31: 0.51 | H31: 0.56 | I31: 0.63
A32: EBITDA | B32: =B26+B27+B29+B30 -> 4.68 | C32: =C26+C27+C29+C30 -> 5.17 | D32: =D26+D27+D29+D30 -> 7.49 | E32: =E26+E27+E29+E30 -> 13.07 | F32: =F26+F27+F29+F30 -> 16.85 | G32: =G26+G27+G29+G30 -> 20.53 | H32: =H26+H27+H29+H30 -> 32.44 | I32: =I26+I27+I29+I30 -> 56.88 | ... K32: =K26+K27+K29+K30 -> 111.93
A39: Quarters
A40: Report Date | B40: 45107 | C40: 45199 | D40: 45291 | E40: 45382 | F40: 45473 | G40: 45565 | H40: 45657 | I40: 45747 | J40: 45838 | K40: 45930
A41: Sales | B41: 295.58 | C41: 219.86 | D41: 226.74 | E41: 282.25 | F41: 320.97 | G41: 306.33 | H41: 308.92 | I41: 330.61 | J41: 328.69 | K41: 352.21
A42: Expenses | B42: 275.07 | C42: 200.85 | D42: 207.82 | E42: 262.55 | F42: 296.16 | G42: 280.78 | H42: 280.21 | I42: 301.16 | J42: 296.96 | K42: 315.09
A43: Other Income | B43: 0.73 | C43: 0.74 | D43: 1.04 | E43: 1.87 | F43: 1.46 | G43: 2.29 | H43: 1.28 | I43: 1.69 | J43: 0.92 | K43: 1.27
A44: Depreciation | B44: 0.38 | C44: 0.38 | D44: 0.38 | E44: 0.38 | F44: 0.35 | G44: 2.05 | H44: 2.09 | I44: 0.53 | J44: 1.48 | K44: 2.68
A45: Interest | B45: 2.25 | C45: 2.24 | D45: 1.89 | E45: 2.42 | F45: 2.26 | G45: 1.69 | H45: 3.4 | I45: 5.87 | J45: 4.94 | K45: 5.06
A46: Profit before tax | B46: 18.61 | C46: 17.13 | D46: 17.69 | E46: 18.77 | F46: 23.66 | G46: 24.1 | H46: 24.5 | I46: 24.74 | J46: 26.23 | K46: 30.65
A47: Tax | B47: 4.58 | C47: 4.55 | D47: 4.63 | E47: 4.49 | F47: 5.98 | G47: 5.85 | H47: 6.2 | I47: 6.57 | J47: 6.63 | K47: 8.06
A48: Net profit | B48: 14.04 | C48: 12.57 | D48: 13.06 | E48: 14.29 | F48: 17.68 | G48: 18.26 | H48: 18.31 | I48: 18.17 | J48: 19.61 | K48: 22.58
A49: Operating Profit | B49: 20.51 | C49: 19.01 | D49: 18.92 | E49: 19.7 | F49: 24.81 | G49: 25.55 | H49: 28.71 | I49: 29.45 | J49: 31.73 | K49: 37.12
A50: EBITDA | B50: =B44+B45+B47+B48 -> 21.25 | C50: =C44+C45+C47+C48 -> 19.74 | D50: =D44+D45+D47+D48 -> 19.96 | E50: =E44+E45+E47+E48 -> 21.58 | F50: =F44+F45+F47+F48 -> 26.27 | G50: =G44+G45+G47+G48 -> 27.85 | H50: =H44+H45+H47+H48 -> 30 | I50: =I44+I45+I47+I48 -> 31.14 | ... K50: =K44+K45+K47+K48 -> 38.38
A54: BALANCE SHEET
A55: Report Date | B55: 42460 | C55: 42825 | D55: 43190 | E55: 43555 | F55: 43921 | G55: 44286 | H55: 44651 | I55: 45016 | J55: 45382 | K55: 45747
A56: Equity Share Capital | B56: 5.92 | C56: 6.38 | D56: 6.91 | E56: 9.17 | F56: 9.17 | G56: 10.13 | H56: 11.28 | I56: 12.69 | J56: 12.71 | K56: 12.73
A57: Reserves | B57: 10.95 | C57: 14.05 | D57: 16.23 | E57: 21.56 | F57: 27.02 | G57: 39.31 | H57: 56.58 | I57: 91.87 | J57: 144.85 | K57: 218.19
...
